
<!-- Copyright (c) 2016-2023 HangZhou YuShu TECHNOLOGY CO.,LTD. ("Unitree Robotics")
All rights reserved.

Redistribution and use in source and binary forms, with or without
modification, are permitted provided that the following conditions are met:

* Redistributions of source code must retain the above copyright notice, this
  list of conditions and the following disclaimer.

* Redistributions in binary form must reproduce the above copyright notice,
  this list of conditions and the following disclaimer in the documentation
  and/or other materials provided with the distribution.

* Neither the name of the copyright holder nor the names of its
  contributors may be used to endorse or promote products derived from
  this software without specific prior written permission.

THIS SOFTWARE IS PROVIDED BY THE COPYRIGHT HOLDERS AND CONTRIBUTORS "AS IS"
AND ANY EXPRESS OR IMPLIED WARRANTIES, INCLUDING, BUT NOT LIMITED TO, THE
IMPLIED WARRANTIES OF MERCHANTABILITY AND FITNESS FOR A PARTICULAR PURPOSE ARE
DISCLAIMED. IN NO EVENT SHALL THE COPYRIGHT HOLDER OR CONTRIBUTORS BE LIABLE
FOR ANY DIRECT, INDIRECT, INCIDENTAL, SPECIAL, EXEMPLARY, OR CONSEQUENTIAL
DAMAGES (INCLUDING, BUT NOT LIMITED TO, PROCUREMENT OF SUBSTITUTE GOODS OR
SERVICES; LOSS OF USE, DATA, OR PROFITS; OR BUSINESS INTERRUPTION) HOWEVER
CAUSED AND ON ANY THEORY OF LIABILITY, WHETHER IN CONTRACT, STRICT LIABILITY,
OR TORT (INCLUDING NEGLIGENCE OR OTHERWISE) ARISING IN ANY WAY OUT OF THE USE
OF THIS SOFTWARE, EVEN IF ADVISED OF THE POSSIBILITY OF SUCH DAMAGE.


Modified by Firas Al-Hafez 2024.
 -->

<mujoco model="h1">
  <compiler angle="radian" meshdir="assets" autolimits="true"/>

  <include file="../common/scene.xml"/>
  <include file="../common/mimic_sites.xml"/>

  <default>
    <default class="h1">
      <geom type="mesh"/>
      <joint damping="1" armature="0.1"/>
      <default class="visual">
        <geom contype="0" conaffinity="0" group="0" material="black"/>
      </default>
      <default class="collision">
        <geom group="1" mass="0" density="0"/>
      </default>
      <site size="0.001" rgba="0.5 0.5 0.5 0.3" group="4"/>
    </default>
    <motor ctrllimited="true"/>

    <default class="b">
      <joint limited="true" stiffness="0.20000000000000001" range="-0.78539816339744828 0.15707963267948966" armature="0.0001" damping="0.070000000000000007"/>
  </default>
  </default>
  <asset>
    <material name="black" rgba="0.1 0.1 0.1 1"/>
    <material name="white" rgba="1 1 1 1"/>
    <!-- MATERIALE AGGIUNTO PER LA PROTESI -->
    <material name="prosthesis_material" rgba="0.29999999999999999 0.29999999999999999 0.29999999999999999 1"/>

    <mesh file="pelvis.stl"/>
    <mesh file="left_hip_yaw_link.stl"/>
    <mesh file="left_hip_roll_link.stl"/>
    <mesh file="left_hip_pitch_link.stl"/>
    <mesh file="left_knee_link.stl"/>
    <mesh file="left_ankle_link.stl"/>
    <mesh file="right_hip_yaw_link.stl"/>
    <mesh file="right_hip_roll_link.stl"/>
    <mesh file="right_hip_pitch_link.stl"/>
    <mesh file="right_knee_link.stl"/>
    <mesh file="right_ankle_link.stl"/>
    <mesh file="torso_link.stl"/>
    <mesh file="left_shoulder_pitch_link.stl"/>
    <mesh file="left_shoulder_roll_link.stl"/>
    <mesh file="left_shoulder_yaw_link.stl"/>
    <mesh file="left_elbow_link.stl"/>
    <mesh file="right_shoulder_pitch_link.stl"/>
    <mesh file="right_shoulder_roll_link.stl"/>
    <mesh file="right_shoulder_yaw_link.stl"/>
    <mesh file="right_elbow_link.stl"/>
    <mesh file="logo_link.stl"/>


 <mesh name="heel_v2_vall" file="heel_v2_vall.stl" scale="0.001 0.001 0.001"/>
    <mesh name="heel_link_v1_2" file="heel_link_v1_2.stl" scale="0.001 0.001 0.001"/>
    <mesh name="rollover_link_v1_2" file="rollover_link_v1_2.stl" scale="0.001 0.001 0.001"/>
    <mesh name="phalanx_softfoot_heel" file="phalanx_softfoot_heel.stl" scale="0.001 0.001 0.001"/>
    <mesh name="phalanx_softfoot_size_m" file="phalanx_softfoot_size_m.stl" scale="0.001 0.001 0.001"/>
    <mesh name="phalanx_softfoot_size_reverse" file="phalanx_softfoot_size_reverse.stl" scale="0.001 0.001 0.001"/>
    <mesh name="phalanx_softfoot_roll" file="phalanx_softfoot_roll.stl" scale="0.001 0.001 0.001"/>
    <mesh name="phalanx_softfoot_distal" file="phalanx_softfoot_distal.stl" scale="0.001 0.001 0.001"/>

  </asset>

  <worldbody>
    <body name="pelvis" pos="0 0 1.045" childclass="h1">
      <site name="pelvis_mimic" class="mimic"/>
      <inertial pos="-0.0002 4e-05 -0.04522" quat="0.498303 0.499454 -0.500496 0.501741" mass="5.39"
        diaginertia="0.0490211 0.0445821 0.00824619"/>
      <light name="spotlight" mode="trackcom" pos="0 -2 50" dir="0 0 -1"/>
      <freejoint name="root"/>
      <geom class="visual" mesh="pelvis"/>
      <geom class="collision" mesh="pelvis"/>
      <body name="left_hip_yaw_link" pos="0 0.0875 -0.1742">
        <site name="left_hip_mimic" class="mimic"  pos="0.05 0.0 0.0"/>
        <inertial pos="-0.04923 0.0001 0.0072" quat="0.69699 0.219193 0.233287 0.641667" mass="2.244"
          diaginertia="0.00304494 0.00296885 0.00189201"/>
        <joint name="hip_rotation_l" axis="0 0 1" range="-0.43 0.43"/>
        <geom class="visual" mesh="left_hip_yaw_link"/>
        <geom size="0.06 0.035" pos="-0.067 0 0" quat="0.707123 0 0.70709 0" type="cylinder" class="collision"/>
        <body name="left_hip_roll_link" pos="0.039468 0 0">
          <inertial pos="-0.0058 -0.00319 -9e-05" quat="0.0438242 0.70721 -0.0729075 0.701867" mass="2.232"
            diaginertia="0.00243264 0.00225325 0.00205492"/>
          <joint name="hip_adduction_l" axis="1 0 0" range="-0.43 0.43"/>
          <geom class="visual" mesh="left_hip_roll_link"/>
          <geom class="collision" mesh="left_hip_roll_link"/>
          <body name="left_hip_pitch_link" pos="0 0.11536 0">
            <inertial pos="0.00746 -0.02346 -0.08193" quat="0.979828 0.0513522 -0.0169854 -0.192382" mass="4.152"
              diaginertia="0.0829503 0.0821457 0.00510909"/>
            <joint name="hip_flexion_l" axis="0 1 0" range="-1.57 1.57"/>
            <geom class="visual" mesh="left_hip_pitch_link"/>
            <geom class="collision" mesh="left_hip_pitch_link"/>
            <body name="left_knee_link" pos="0 0 -0.4">
              <site name="left_knee_mimic" class="mimic"/>
              <inertial pos="-0.00136 -0.00512 -0.1384" quat="0.626132 -0.034227 -0.0416277 0.777852" mass="1.721"
                diaginertia="0.0125237 0.0123104 0.0019428"/>
              <joint name="knee_angle_l" axis="0 1 0" range="-0.26 2.05"/>
              <geom class="visual" mesh="left_knee_link"/>
              <geom class="collision" mesh="left_knee_link"/>
              <body name="left_ankle_link" pos="0 0 -0.4">
                <site name="left_foot_mimic" class="mimic" pos="0.075 0.0 -0.05"/>
                <inertial pos="0.06722 0.00015 -0.04497" quat="0.489101 0.503197 0.565782 0.432972" mass="0.446"
                  diaginertia="0.00220848 0.00218961 0.000214202"/>
                <joint name="ankle_angle_l" axis="0 1 0" range="-0.87 0.52"/>
                <geom class="visual" mesh="left_ankle_link"/>
                <geom name="left_foot" class="collision" mesh="left_ankle_link"/>
              </body>
            </body>
          </body>
        </body>
      </body>
      <body name="right_hip_yaw_link" pos="0 -0.0875 -0.15">
        <site name="right_hip_mimic" class="mimic" pos="0.05 0.0 0.0"/>
        <inertial pos="-0.04923 -0.0001 0.0072" quat="0.641667 0.233287 0.219193 0.69699" mass="2.244"
          diaginertia="0.00304494 0.00296885 0.00189201"/>
        <joint name="hip_rotation_r" axis="0 0 1" range="-0.43 0.43"/>
        <geom class="visual" mesh="right_hip_yaw_link"/>
        <geom size="0.06 0.035" pos="-0.067 0 0" quat="0.707123 0 0.70709 0" type="cylinder" class="collision"/>
        <body name="right_hip_roll_link" pos="0.039468 0 0">
          <inertial pos="-0.0058 0.00319 -9e-05" quat="-0.0438242 0.70721 0.0729075 0.701867" mass="2.232"
            diaginertia="0.00243264 0.00225325 0.00205492"/>
          <joint name="hip_adduction_r" axis="1 0 0" range="-0.43 0.43"/>
          <geom class="visual" mesh="right_hip_roll_link"/>
          <geom class="collision" mesh="right_hip_roll_link"/>
          <body name="right_hip_pitch_link" pos="0 -0.11536 0">
            <inertial pos="0.00746 0.02346 -0.08193" quat="0.979828 -0.0513522 -0.0169854 0.192382" mass="4.152"
              diaginertia="0.0829503 0.0821457 0.00510909"/>
            <joint name="hip_flexion_r" axis="0 1 0" range="-1.57 1.57"/>
            <geom class="visual" mesh="right_hip_pitch_link"/>
            <geom class="collision" mesh="right_hip_pitch_link"/>
            <body name="right_knee_link" pos="0 0 -0.4">
              <site name="right_knee_mimic" class="mimic"/>
              <inertial pos="-0.00136 0.00512 -0.1384" quat="0.777852 -0.0416277 -0.034227 0.626132" mass="1.721"
                diaginertia="0.0125237 0.0123104 0.0019428"/>
              <joint name="knee_angle_r" axis="0 1 0" range="-0.26 2.05"/>
              <geom class="visual" mesh="right_knee_link"/>
              <geom class="collision" mesh="right_knee_link"/>
              <body name="right_ankle_link" pos="0 0 -0.4">
                <site name="right_foot_mimic" class="mimic" pos="0.075 0.0 -0.05"/>
                <inertial pos="0.06722 -0.00015 -0.04497" quat="0.432972 0.565782 0.503197 0.489101" mass="0.446"
                  diaginertia="0.00220848 0.00218961 0.000214202"/>
                <joint name="ankle_angle_r" axis="0 1 0" range="-0.87 0.52"/>
                <!-- Original foot geometries removed -->
                <!-- <geom class="visual" mesh="right_ankle_link"/> -->
                <!-- <geom name="right_foot" class="collision" mesh="right_ankle_link"/> -->
                
                <!-- =========== START OF PROSTHESIS DEFINITION =========== -->
                <body name="posterior_arch" pos="0.02 0 0.02" quat="1 1 0 0">
                  <inertial pos="-0.0094524164999999997 -0.032786418999999997 -0.0019973598" quat="0.68119730000000001 0.190553 0.68065509999999996 -0.19070480000000001" mass="0.12747079" diaginertia="0.0001165642 5.3305450999999999e-05 0.00012416468000000001"/>
                  <joint name="ankle_joint" />
                  <geom name="unnamed_geom_0_coll" class="b" type="mesh" contype="1" conaffinity="4" group="1" rgba="0.29999999999999999 0.29999999999999999 0.29999999999999999 1" mesh="heel_link_v1_2"/>
                  <geom name="unnamed_geom_0_vis" class="visual" type="mesh" mesh="heel_link_v1_2" material="prosthesis_material"/>
                  <body name="heel" pos="-0.037594799999999998 -0.089337299999999994 -0.0040000000000000001" quat="0.99247200000000002 0 0 -0.12246799999999999">
                    <inertial pos="1.3043e-05 -0.0021390100000000002 1.97167e-05" quat="0.67342000000000002 0.00083539200000000001 0.00085681400000000001 0.739259" mass="0.175985" diaginertia="0.000130939 8.4478400000000001e-05 6.2041500000000006e-05"/>
                    <joint name="posterior_arch_to_heel" class="b" pos="0 0 0" axis="0 0 1" stiffness="0" armature="0.0001" damping="0.0001"/>
                    <geom name="unnamed_geom_1_coll" class="b" type="mesh" contype="1" conaffinity="2" group="1" rgba="0.90000000000000002 0.90000000000000002 0.90000000000000002 1" mesh="heel_v2_vall"/>
                    <geom name="unnamed_geom_1_vis" class="visual" type="mesh" mesh="heel_v2_vall" material="prosthesis_material"/>
                    <geom name="unnamed_geom_2_coll" class="b" type="mesh" contype="1" conaffinity="2" group="1" rgba="0.29999999999999999 0.29999999999999999 0.29999999999999999 1" pos="0 0 -0.032000000000000001" mesh="phalanx_softfoot_heel"/>
                    <geom name="unnamed_geom_2_vis" class="visual" type="mesh" pos="0 0 -0.032000000000000001" mesh="phalanx_softfoot_heel" material="prosthesis_material"/>
                    <geom name="unnamed_geom_3_coll" class="b" type="mesh" contype="1" conaffinity="2" group="1" rgba="0.29999999999999999 0.29999999999999999 0.29999999999999999 1" pos="0 0 -0.016" mesh="phalanx_softfoot_heel"/>
                    <geom name="unnamed_geom_3_vis" class="visual" type="mesh" pos="0 0 -0.016" mesh="phalanx_softfoot_heel" material="prosthesis_material"/>
                    <geom name="unnamed_geom_4_coll" class="b" type="mesh" contype="1" conaffinity="2" group="1" rgba="0.29999999999999999 0.29999999999999999 0.29999999999999999 1" mesh="phalanx_softfoot_heel"/>
                    <geom name="unnamed_geom_4_vis" class="visual" type="mesh" mesh="phalanx_softfoot_heel" material="prosthesis_material"/>
                    <geom name="unnamed_geom_5_coll" class="b" type="mesh" contype="1" conaffinity="2" group="1" rgba="0.29999999999999999 0.29999999999999999 0.29999999999999999 1" pos="0 0 0.016" mesh="phalanx_softfoot_heel"/>
                    <geom name="unnamed_geom_5_vis" class="visual" type="mesh" pos="0 0 0.016" mesh="phalanx_softfoot_heel" material="prosthesis_material"/>
                    <geom name="unnamed_geom_6_coll" class="b" type="mesh" contype="1" conaffinity="2" group="1" rgba="0.29999999999999999 0.29999999999999999 0.29999999999999999 1" pos="0 0 0.032000000000000001" mesh="phalanx_softfoot_heel"/>
                    <geom name="unnamed_geom_6_vis" class="visual" type="mesh" pos="0 0 0.032000000000000001" mesh="phalanx_softfoot_heel" material="prosthesis_material"/>
                    <body name="virtual_1_1" pos="0.0251205 0 -0.032000000000000001" quat="0.99680500000000005 0 0 0.079871200000000003">
                      <inertial pos="0 0 0" mass="9.9999999999999995e-07" diaginertia="9.9999999999999995e-07 9.9999999999999995e-07 9.9999999999999995e-07"/>
                      <joint name="heel_phalanx_1_to_virtual_1_1" class="b" pos="0 0 0" axis="0 0 1"/>
                      <body name="phalanx_1_1" pos="0.014 0 0">
                        <inertial pos="0.0062735100000000004 -0.00081271999999999996 8.0566200000000001e-05" quat="0 0.70710700000000004 0 0.70710700000000004" mass="0.0069452999999999997" diaginertia="7.2126499999999997e-07 6.6877600000000003e-07 1.8386400000000001e-07"/>
                        <joint name="virtual_1_1_to_phalanx_1_1" class="b" pos="0 0 0" axis="0 0 1"/>
                        <geom name="unnamed_geom_7_coll" class="b" type="mesh" contype="1" conaffinity="2" group="1" rgba="0.29999999999999999 0.29999999999999999 0.29999999999999999 1" mesh="phalanx_softfoot_size_m"/>
                        <geom name="unnamed_geom_7_vis" class="visual" type="mesh" mesh="phalanx_softfoot_size_m" material="prosthesis_material"/>
                        <body name="virtual_2_1" pos="0.012999999999999999 0 0">
                          <inertial pos="0 0 0" mass="9.9999999999999995e-07" diaginertia="9.9999999999999995e-07 9.9999999999999995e-07 9.9999999999999995e-07"/>
                          <joint name="phalanx_1_1_to_virtual_2_1" class="b" pos="0 0 0" axis="0 0 1"/>
                          <body name="phalanx_2_1" pos="0.014 0 0">
                            <inertial pos="0.0062735100000000004 -0.00081271999999999996 8.0566200000000001e-05" quat="0 0.70710700000000004 0 0.70710700000000004" mass="0.0069452999999999997" diaginertia="7.2126499999999997e-07 6.6877600000000003e-07 1.8386400000000001e-07"/>
                            <joint name="virtual_2_1_to_phalanx_2_1" class="b" pos="0 0 0" axis="0 0 1"/>
                            <geom name="unnamed_geom_8_coll" class="b" type="mesh" contype="1" conaffinity="2" group="1" rgba="0.29999999999999999 0.29999999999999999 0.29999999999999999 1" mesh="phalanx_softfoot_size_m"/>
                            <geom name="unnamed_geom_8_vis" class="visual" type="mesh" mesh="phalanx_softfoot_size_m" material="prosthesis_material"/>
                            <body name="virtual_3_1" pos="0.012999999999999999 0 0">
                              <inertial pos="0 0 0" mass="9.9999999999999995e-07" diaginertia="9.9999999999999995e-07 9.9999999999999995e-07 9.9999999999999995e-07"/>
                              <joint name="phalanx_2_1_to_virtual_3_1" class="b" pos="0 0 0" axis="0 0 1"/>
                              <body name="phalanx_3_1" pos="0.014 0 0">
                                <inertial pos="0.0062735100000000004 -0.00081271999999999996 8.0566200000000001e-05" quat="0 0.70710700000000004 0 0.70710700000000004" mass="0.0069452999999999997" diaginertia="7.2126499999999997e-07 6.6877600000000003e-07 1.8386400000000001e-07"/>
                                <joint name="virtual_3_1_to_phalanx_3_1" class="b" pos="0 0 0" axis="0 0 1"/>
                                <geom name="unnamed_geom_9_coll" class="b" type="mesh" contype="1" conaffinity="2" group="1" rgba="0.29999999999999999 0.29999999999999999 0.29999999999999999 1" mesh="phalanx_softfoot_size_m"/>
                                <geom name="unnamed_geom_9_vis" class="visual" type="mesh" mesh="phalanx_softfoot_size_m" material="prosthesis_material"/>
                                <body name="virtual_4_1" pos="0.012999999999999999 0 0">
                                  <inertial pos="0 0 0" mass="9.9999999999999995e-07" diaginertia="9.9999999999999995e-07 9.9999999999999995e-07 9.9999999999999995e-07"/>
                                  <joint name="phalanx_3_1_to_virtual_4_1" class="b" pos="0 0 0" axis="0 0 1"/>
                                  <body name="reverse_phalanx_1" pos="0.014 0 0" quat="0.99780500000000005 0 0 -0.066227400000000006">
                                    <inertial pos="0.0071278000000000001 0.000123001 7.7890899999999997e-05" quat="0.70710700000000004 0 0 0.70710700000000004" mass="0.0070074899999999999" diaginertia="2.2284600000000001e-07 2.2284600000000001e-07 2.2284600000000001e-07"/>
                                    <joint name="virtual_4_1_to_reverse_phalanx_1" class="b" pos="0 0 0" axis="0 0 1"/>
                                    <geom name="unnamed_geom_10_coll" class="b" type="mesh" contype="1" conaffinity="8" group="1" rgba="0.29999999999999999 0.29999999999999999 0.29999999999999999 1" mesh="phalanx_softfoot_size_reverse"/>
                                    <geom name="unnamed_geom_10_vis" class="visual" type="mesh" mesh="phalanx_softfoot_size_reverse" material="prosthesis_material"/>
                                    <body name="virtual_5_1" pos="0.015132700000000001 0 0" quat="0.99780500000000005 0 0 0.066227400000000006">
                                      <inertial pos="0 0 0" mass="9.9999999999999995e-07" diaginertia="9.9999999999999995e-07 9.9999999999999995e-07 9.9999999999999995e-07"/>
                                      <joint name="reverse_phalanx_1_to_virtual_5_1" class="b" pos="0 0 0" axis="0 0 1" range="-0.15707963267948966 0.78539816339744828"/>
                                      <body name="rollover_phalanx_1" pos="0.014 0 0" quat="0.99748400000000004 0 0 0.070888800000000002">
                                        <inertial pos="0.0071752400000000003 0.0022867999999999999 -1.01402e-05" quat="0.70710700000000004 0.70710700000000004 0 0" mass="0.014041700000000001" diaginertia="0.0021245399999999998 0.0021245399999999998 0.0021245399999999998"/>
                                        <joint name="virtual_5_1_to_rollover_phalanx_1" class="b" pos="0 0 0" axis="0 0 1" range="-0.15707963267948966 0.78539816339744828"/>
                                        <geom name="unnamed_geom_11_coll" class="b" type="mesh" contype="1" conaffinity="8" group="1" rgba="0.90000000000000002 0.90000000000000002 0.90000000000000002 1" mesh="phalanx_softfoot_roll"/>
                                        <geom name="unnamed_geom_11_vis" class="visual" type="mesh" mesh="phalanx_softfoot_roll" material="prosthesis_material"/>
                                        <body name="virtual_6_1" pos="0.014142099999999999 0 0" quat="0.99748400000000004 0 0 -0.070888800000000002">
                                          <inertial pos="0 0 0" mass="9.9999999999999995e-07" diaginertia="9.9999999999999995e-07 9.9999999999999995e-07 9.9999999999999995e-07"/>
                                          <joint name="rollover_phalanx_1_to_virtual_6_1" class="b" pos="0 0 0" axis="0 0 1"/>
                                          <body name="phalanx_4_1" pos="0.014 0 0">
                                            <inertial pos="0.0062735100000000004 -0.00081271999999999996 8.0566200000000001e-05" quat="0 0.70710700000000004 0 0.70710700000000004" mass="0.0069452999999999997" diaginertia="7.2126499999999997e-07 6.6877600000000003e-07 1.8386400000000001e-07"/>
                                            <joint name="virtual_6_1_to_phalanx_4_1" class="b" pos="0 0 0" axis="0 0 1"/>
                                            <geom name="unnamed_geom_12_coll" class="b" type="mesh" contype="1" conaffinity="2" group="1" rgba="0.29999999999999999 0.29999999999999999 0.29999999999999999 1" mesh="phalanx_softfoot_size_m"/>
                                            <geom name="unnamed_geom_12_vis" class="visual" type="mesh" mesh="phalanx_softfoot_size_m" material="prosthesis_material"/>
                                            <body name="virtual_7_1" pos="0.012999999999999999 0 0">
                                              <inertial pos="0 0 0" mass="9.9999999999999995e-07" diaginertia="9.9999999999999995e-07 9.9999999999999995e-07 9.9999999999999995e-07"/>
                                              <joint name="phalanx_4_1_to_virtual_7_1" class="b" pos="0 0 0" axis="0 0 1"/>
                                              <body name="distal_phalanx_1" pos="0.014 0 0">
                                                <inertial pos="0.0036580200000000001 -0.00070785200000000003 0.000211358" quat="0.100463 0.69993399999999995 -0.100463 0.69993399999999995" mass="0.0052713899999999999" diaginertia="2.4732799999999998e-07 2.26785e-07 1.27455e-07"/>
                                                <joint name="virtual_7_1_to_distal_phalanx_1" class="b" pos="0 0 0" axis="0 0 1"/>
                                                <geom name="unnamed_geom_13_coll" class="b" type="mesh" contype="1" conaffinity="2" group="1" rgba="0.90000000000000002 0.90000000000000002 0.90000000000000002 1" mesh="phalanx_softfoot_distal"/>
                                                <geom name="unnamed_geom_13_vis" class="visual" type="mesh" mesh="phalanx_softfoot_distal" material="prosthesis_material"/>
                                                <geom name="roll_distal_phalanx_1" class="b" type="cylinder" contype="0" conaffinity="0" group="4" size="0.0040000000000000001 0.0054999999999999997" rgba="0.10000000000000001 0.80000000000000004 0.10000000000000001 1" pos="0 0 0"/>
                                                <site name="site_roll_distal_phalanx_1" class="b" size="0.001 0.001 0.001" pos="0 -0.0047000000000000002 0"/>
                                                <site name="site_roll_distal_phalanx_1_extreme" class="b" size="0.001 0.001 0.001" pos="0.012999999999999999 -0.0047000000000000002 0"/>
                                              </body>
                                              <geom name="roll_virtual_7_1" class="b" type="cylinder" contype="0" conaffinity="0" group="4" size="0.0040000000000000001 0.0054999999999999997" rgba="0.10000000000000001 0.80000000000000004 0.10000000000000001 1" pos="0 0 0"/>
                                              <site name="site_roll_virtual_7_1" class="b" size="0.001 0.001 0.001" pos="0 -0.0047000000000000002 0"/>
                                            </body>
                                            <geom name="roll_phalanx_4_1" class="b" type="cylinder" contype="0" conaffinity="0" group="4" size="0.0040000000000000001 0.0054999999999999997" rgba="0.10000000000000001 0.80000000000000004 0.10000000000000001 1" pos="0 0 0"/>
                                            <site name="site_roll_phalanx_4_1" class="b" size="0.001 0.001 0.001" pos="0 -0.0047000000000000002 0"/>
                                          </body>
                                          <geom name="roll_virtual_6_1" class="b" type="cylinder" contype="0" conaffinity="0" group="4" size="0.0040000000000000001 0.0054999999999999997" rgba="0.10000000000000001 0.80000000000000004 0.10000000000000001 1" pos="0 0 0"/>
                                          <site name="site_roll_virtual_6_1" class="b" size="0.001 0.001 0.001" pos="0 -0.0047000000000000002 0"/>
                                        </body>
                                        <geom name="roll_rollover_phalanx_1" class="b" type="cylinder" contype="0" conaffinity="0" group="4" size="0.0040000000000000001 0.0054999999999999997" rgba="0.10000000000000001 0.80000000000000004 0.10000000000000001 1" pos="0 0 0"/>
                                        <site name="site_roll_rollover_phalanx_1" class="b" size="0.001 0.001 0.001" pos="0 0.0047000000000000002 0"/>
                                      </body>
                                      <geom name="roll_virtual_5_1" class="b" type="cylinder" contype="0" conaffinity="0" group="4" size="0.0040000000000000001 0.0054999999999999997" rgba="0.10000000000000001 0.80000000000000004 0.10000000000000001 1" pos="0 0 0"/>
                                      <site name="site_roll_virtual_5_1" class="b" size="0.001 0.001 0.001" pos="0 0.0047000000000000002 0"/>
                                    </body>
                                    <geom name="roll_reverse_phalanx_1" class="b" type="cylinder" contype="0" conaffinity="0" group="4" size="0.0040000000000000001 0.0054999999999999997" rgba="0.10000000000000001 0.80000000000000004 0.10000000000000001 1" pos="0 0 0"/>
                                    <site name="site_roll_reverse_phalanx_1" class="b" size="0.001 0.001 0.001" pos="0 -0.0047000000000000002 0"/>
                                  </body>
                                  <geom name="roll_virtual_4_1" class="b" type="cylinder" contype="0" conaffinity="0" group="4" size="0.0040000000000000001 0.0054999999999999997" rgba="0.10000000000000001 0.80000000000000004 0.10000000000000001 1" pos="0 0 0"/>
                                  <site name="site_roll_virtual_4_1" class="b" size="0.001 0.001 0.001" pos="0 -0.0047000000000000002 0"/>
                                </body>
                                <geom name="roll_phalanx_3_1" class="b" type="cylinder" contype="0" conaffinity="0" group="4" size="0.0040000000000000001 0.0054999999999999997" rgba="0.10000000000000001 0.80000000000000004 0.10000000000000001 1" pos="0 0 0"/>
                                <site name="site_roll_phalanx_3_1" class="b" size="0.001 0.001 0.001" pos="0 -0.0047000000000000002 0"/>
                              </body>
                              <geom name="roll_virtual_3_1" class="b" type="cylinder" contype="0" conaffinity="0" group="4" size="0.0040000000000000001 0.0054999999999999997" rgba="0.10000000000000001 0.80000000000000004 0.10000000000000001 1" pos="0 0 0"/>
                              <site name="site_roll_virtual_3_1" class="b" size="0.001 0.001 0.001" pos="0 -0.0047000000000000002 0"/>
                            </body>
                            <geom name="roll_phalanx_2_1" class="b" type="cylinder" contype="0" conaffinity="0" group="4" size="0.0040000000000000001 0.0054999999999999997" rgba="0.10000000000000001 0.80000000000000004 0.10000000000000001 1" pos="0 0 0"/>
                            <site name="site_roll_phalanx_2_1" class="b" size="0.001 0.001 0.001" pos="0 -0.0047000000000000002 0"/>
                          </body>
                          <geom name="roll_virtual_2_1" class="b" type="cylinder" contype="0" conaffinity="0" group="4" size="0.0040000000000000001 0.0054999999999999997" rgba="0.10000000000000001 0.80000000000000004 0.10000000000000001 1" pos="0 0 0"/>
                          <site name="site_roll_virtual_2_1" class="b" size="0.001 0.001 0.001" pos="0 -0.0047000000000000002 0"/>
                        </body>
                        <geom name="roll_phalanx_1_1" class="b" type="cylinder" contype="0" conaffinity="0" group="4" size="0.0040000000000000001 0.0054999999999999997" rgba="0.10000000000000001 0.80000000000000004 0.10000000000000001 1" pos="0 0 0"/>
                        <site name="site_roll_phalanx_1_1" class="b" size="0.001 0.001 0.001" pos="0 -0.0047000000000000002 0"/>
                      </body>
                      <geom name="roll_virtual_1_1" class="b" type="cylinder" contype="0" conaffinity="0" group="4" size="0.0040000000000000001 0.0054999999999999997" rgba="0.10000000000000001 0.80000000000000004 0.10000000000000001 1" pos="0 0 0"/>
                      <site name="site_roll_virtual_1_1" class="b" size="0.001 0.001 0.001" pos="0 -0.0047000000000000002 0"/>
                    </body>
                    <body name="virtual_1_2" pos="0.0251205 0 -0.016" quat="0.99680500000000005 0 0 0.079871200000000003">
                      <inertial pos="0 0 0" mass="9.9999999999999995e-07" diaginertia="9.9999999999999995e-07 9.9999999999999995e-07 9.9999999999999995e-07"/>
                      <joint name="heel_phalanx_2_to_virtual_1_2" class="b" pos="0 0 0" axis="0 0 1"/>
                      <body name="phalanx_1_2" pos="0.014 0 0">
                        <inertial pos="0.0062735100000000004 -0.00081271999999999996 8.0566200000000001e-05" quat="0 0.70710700000000004 0 0.70710700000000004" mass="0.0069452999999999997" diaginertia="7.2126499999999997e-07 6.6877600000000003e-07 1.8386400000000001e-07"/>
                        <joint name="virtual_1_2_to_phalanx_1_2" class="b" pos="0 0 0" axis="0 0 1"/>
                        <geom name="unnamed_geom_28_coll" class="b" type="mesh" contype="1" conaffinity="2" group="1" rgba="0.29999999999999999 0.29999999999999999 0.29999999999999999 1" mesh="phalanx_softfoot_size_m"/>
                        <geom name="unnamed_geom_28_vis" class="visual" type="mesh" mesh="phalanx_softfoot_size_m" material="prosthesis_material"/>
                        <body name="virtual_2_2" pos="0.012999999999999999 0 0">
                          <inertial pos="0 0 0" mass="9.9999999999999995e-07" diaginertia="9.9999999999999995e-07 9.9999999999999995e-07 9.9999999999999995e-07"/>
                          <joint name="phalanx_1_2_to_virtual_2_2" class="b" pos="0 0 0" axis="0 0 1"/>
                          <body name="phalanx_2_2" pos="0.014 0 0">
                            <inertial pos="0.0062735100000000004 -0.00081271999999999996 8.0566200000000001e-05" quat="0 0.70710700000000004 0 0.70710700000000004" mass="0.0069452999999999997" diaginertia="7.2126499999999997e-07 6.6877600000000003e-07 1.8386400000000001e-07"/>
                            <joint name="virtual_2_2_to_phalanx_2_2" class="b" pos="0 0 0" axis="0 0 1"/>
                            <geom name="unnamed_geom_29_coll" class="b" type="mesh" contype="1" conaffinity="2" group="1" rgba="0.29999999999999999 0.29999999999999999 0.29999999999999999 1" mesh="phalanx_softfoot_size_m"/>
                            <geom name="unnamed_geom_29_vis" class="visual" type="mesh" mesh="phalanx_softfoot_size_m" material="prosthesis_material"/>
                            <body name="virtual_3_2" pos="0.012999999999999999 0 0">
                              <inertial pos="0 0 0" mass="9.9999999999999995e-07" diaginertia="9.9999999999999995e-07 9.9999999999999995e-07 9.9999999999999995e-07"/>
                              <joint name="phalanx_2_2_to_virtual_3_2" class="b" pos="0 0 0" axis="0 0 1"/>
                              <body name="phalanx_3_2" pos="0.014 0 0">
                                <inertial pos="0.0062735100000000004 -0.00081271999999999996 8.0566200000000001e-05" quat="0 0.70710700000000004 0 0.70710700000000004" mass="0.0069452999999999997" diaginertia="7.2126499999999997e-07 6.6877600000000003e-07 1.8386400000000001e-07"/>
                                <joint name="virtual_3_2_to_phalanx_3_2" class="b" pos="0 0 0" axis="0 0 1"/>
                                <geom name="unnamed_geom_30_coll" class="b" type="mesh" contype="1" conaffinity="2" group="1" rgba="0.29999999999999999 0.29999999999999999 0.29999999999999999 1" mesh="phalanx_softfoot_size_m"/>
                                <geom name="unnamed_geom_30_vis" class="visual" type="mesh" mesh="phalanx_softfoot_size_m" material="prosthesis_material"/>
                                <body name="virtual_4_2" pos="0.012999999999999999 0 0">
                                  <inertial pos="0 0 0" mass="9.9999999999999995e-07" diaginertia="9.9999999999999995e-07 9.9999999999999995e-07 9.9999999999999995e-07"/>
                                  <joint name="phalanx_3_2_to_virtual_4_2" class="b" pos="0 0 0" axis="0 0 1"/>
                                  <body name="reverse_phalanx_2" pos="0.014 0 0" quat="0.99780500000000005 0 0 -0.066227400000000006">
                                    <inertial pos="0.0071278000000000001 0.000123001 7.7890899999999997e-05" quat="0.70710700000000004 0 0 0.70710700000000004" mass="0.0070074899999999999" diaginertia="2.2284600000000001e-07 2.2284600000000001e-07 2.2284600000000001e-07"/>
                                    <joint name="virtual_4_2_to_reverse_phalanx_2" class="b" pos="0 0 0" axis="0 0 1"/>
                                    <geom name="unnamed_geom_31_coll" class="b" type="mesh" contype="1" conaffinity="8" group="1" rgba="0.29999999999999999 0.29999999999999999 0.29999999999999999 1" mesh="phalanx_softfoot_size_reverse"/>
                                    <geom name="unnamed_geom_31_vis" class="visual" type="mesh" mesh="phalanx_softfoot_size_reverse" material="prosthesis_material"/>
                                    <body name="virtual_5_2" pos="0.015132700000000001 0 0" quat="0.99780500000000005 0 0 0.066227400000000006">
                                      <inertial pos="0 0 0" mass="9.9999999999999995e-07" diaginertia="9.9999999999999995e-07 9.9999999999999995e-07 9.9999999999999995e-07"/>
                                      <joint name="reverse_phalanx_2_to_virtual_5_2" class="b" pos="0 0 0" axis="0 0 1" range="-0.15707963267948966 0.78539816339744828"/>
                                      <body name="rollover_phalanx_2" pos="0.014 0 0" quat="0.99748400000000004 0 0 0.070888800000000002">
                                        <inertial pos="0.0071752400000000003 0.0022867999999999999 -1.01402e-05" quat="0.70710700000000004 0.70710700000000004 0 0" mass="0.014041700000000001" diaginertia="0.0021245399999999998 0.0021245399999999998 0.0021245399999999998"/>
                                        <joint name="virtual_5_2_to_rollover_phalanx_2" class="b" pos="0 0 0" axis="0 0 1" range="-0.15707963267948966 0.78539816339744828"/>
                                        <geom name="unnamed_geom_32_coll" class="b" type="mesh" contype="1" conaffinity="8" group="1" rgba="0.90000000000000002 0.90000000000000002 0.90000000000000002 1" mesh="phalanx_softfoot_roll"/>
                                        <geom name="unnamed_geom_32_vis" class="visual" type="mesh" mesh="phalanx_softfoot_roll" material="prosthesis_material"/>
                                        <body name="virtual_6_2" pos="0.014142099999999999 0 0" quat="0.99748400000000004 0 0 -0.070888800000000002">
                                          <inertial pos="0 0 0" mass="9.9999999999999995e-07" diaginertia="9.9999999999999995e-07 9.9999999999999995e-07 9.9999999999999995e-07"/>
                                          <joint name="rollover_phalanx_2_to_virtual_6_2" class="b" pos="0 0 0" axis="0 0 1"/>
                                          <body name="phalanx_4_2" pos="0.014 0 0">
                                            <inertial pos="0.0062735100000000004 -0.00081271999999999996 8.0566200000000001e-05" quat="0 0.70710700000000004 0 0.70710700000000004" mass="0.0069452999999999997" diaginertia="7.2126499999999997e-07 6.6877600000000003e-07 1.8386400000000001e-07"/>
                                            <joint name="virtual_6_2_to_phalanx_4_2" class="b" pos="0 0 0" axis="0 0 1"/>
                                            <geom name="unnamed_geom_33_coll" class="b" type="mesh" contype="1" conaffinity="2" group="1" rgba="0.29999999999999999 0.29999999999999999 0.29999999999999999 1" mesh="phalanx_softfoot_size_m"/>
                                            <geom name="unnamed_geom_33_vis" class="visual" type="mesh" mesh="phalanx_softfoot_size_m" material="prosthesis_material"/>
                                            <body name="virtual_7_2" pos="0.012999999999999999 0 0">
                                              <inertial pos="0 0 0" mass="9.9999999999999995e-07" diaginertia="9.9999999999999995e-07 9.9999999999999995e-07 9.9999999999999995e-07"/>
                                              <joint name="phalanx_4_2_to_virtual_7_2" class="b" pos="0 0 0" axis="0 0 1"/>
                                              <body name="distal_phalanx_2" pos="0.014 0 0">
                                                <inertial pos="0.0036580200000000001 -0.00070785200000000003 0.000211358" quat="0.100463 0.69993399999999995 -0.100463 0.69993399999999995" mass="0.0052713899999999999" diaginertia="2.4732799999999998e-07 2.26785e-07 1.27455e-07"/>
                                                <joint name="virtual_7_2_to_distal_phalanx_2" class="b" pos="0 0 0" axis="0 0 1"/>
                                                <geom name="unnamed_geom_34_coll" class="b" type="mesh" contype="1" conaffinity="2" group="1" rgba="0.90000000000000002 0.90000000000000002 0.90000000000000002 1" mesh="phalanx_softfoot_distal"/>
                                                <geom name="unnamed_geom_34_vis" class="visual" type="mesh" mesh="phalanx_softfoot_distal" material="prosthesis_material"/>
                                                <geom name="roll_distal_phalanx_2" class="b" type="cylinder" contype="0" conaffinity="0" group="4" size="0.0040000000000000001 0.0054999999999999997" rgba="0.10000000000000001 0.80000000000000004 0.10000000000000001 1" pos="0 0 0"/>
                                                <site name="site_roll_distal_phalanx_2" class="b" size="0.001 0.001 0.001" pos="0 -0.0047000000000000002 0"/>
                                                <site name="site_roll_distal_phalanx_2_extreme" class="b" size="0.001 0.001 0.001" pos="0.012999999999999999 -0.0047000000000000002 0"/>
                                              </body>
                                              <geom name="roll_virtual_7_2" class="b" type="cylinder" contype="0" conaffinity="0" group="4" size="0.0040000000000000001 0.0054999999999999997" rgba="0.10000000000000001 0.80000000000000004 0.10000000000000001 1" pos="0 0 0"/>
                                              <site name="site_roll_virtual_7_2" class="b" size="0.001 0.001 0.001" pos="0 -0.0047000000000000002 0"/>
                                            </body>
                                            <geom name="roll_phalanx_4_2" class="b" type="cylinder" contype="0" conaffinity="0" group="4" size="0.0040000000000000001 0.0054999999999999997" rgba="0.10000000000000001 0.80000000000000004 0.10000000000000001 1" pos="0 0 0"/>
                                            <site name="site_roll_phalanx_4_2" class="b" size="0.001 0.001 0.001" pos="0 -0.0047000000000000002 0"/>
                                          </body>
                                          <geom name="roll_virtual_6_2" class="b" type="cylinder" contype="0" conaffinity="0" group="4" size="0.0040000000000000001 0.0054999999999999997" rgba="0.10000000000000001 0.80000000000000004 0.10000000000000001 1" pos="0 0 0"/>
                                          <site name="site_roll_virtual_6_2" class="b" size="0.001 0.001 0.001" pos="0 -0.0047000000000000002 0"/>
                                        </body>
                                        <geom name="roll_rollover_phalanx_2" class="b" type="cylinder" contype="0" conaffinity="0" group="4" size="0.0040000000000000001 0.0054999999999999997" rgba="0.10000000000000001 0.80000000000000004 0.10000000000000001 1" pos="0 0 0"/>
                                        <site name="site_roll_rollover_phalanx_2" class="b" size="0.001 0.001 0.001" pos="0 0.0047000000000000002 0"/>
                                      </body>
                                      <geom name="roll_virtual_5_2" class="b" type="cylinder" contype="0" conaffinity="0" group="4" size="0.0040000000000000001 0.0054999999999999997" rgba="0.10000000000000001 0.80000000000000004 0.10000000000000001 1" pos="0 0 0"/>
                                      <site name="site_roll_virtual_5_2" class="b" size="0.001 0.001 0.001" pos="0 0.0047000000000000002 0"/>
                                    </body>
                                    <geom name="roll_reverse_phalanx_2" class="b" type="cylinder" contype="0" conaffinity="0" group="4" size="0.0040000000000000001 0.0054999999999999997" rgba="0.10000000000000001 0.80000000000000004 0.10000000000000001 1" pos="0 0 0"/>
                                    <site name="site_roll_reverse_phalanx_2" class="b" size="0.001 0.001 0.001" pos="0 -0.0047000000000000002 0"/>
                                  </body>
                                  <geom name="roll_virtual_4_2" class="b" type="cylinder" contype="0" conaffinity="0" group="4" size="0.0040000000000000001 0.0054999999999999997" rgba="0.10000000000000001 0.80000000000000004 0.10000000000000001 1" pos="0 0 0"/>
                                  <site name="site_roll_virtual_4_2" class="b" size="0.001 0.001 0.001" pos="0 -0.0047000000000000002 0"/>
                                </body>
                                <geom name="roll_phalanx_3_2" class="b" type="cylinder" contype="0" conaffinity="0" group="4" size="0.0040000000000000001 0.0054999999999999997" rgba="0.10000000000000001 0.80000000000000004 0.10000000000000001 1" pos="0 0 0"/>
                                <site name="site_roll_phalanx_3_2" class="b" size="0.001 0.001 0.001" pos="0 -0.0047000000000000002 0"/>
                              </body>
                              <geom name="roll_virtual_3_2" class="b" type="cylinder" contype="0" conaffinity="0" group="4" size="0.0040000000000000001 0.0054999999999999997" rgba="0.10000000000000001 0.80000000000000004 0.10000000000000001 1" pos="0 0 0"/>
                              <site name="site_roll_virtual_3_2" class="b" size="0.001 0.001 0.001" pos="0 -0.0047000000000000002 0"/>
                            </body>
                            <geom name="roll_phalanx_2_2" class="b" type="cylinder" contype="0" conaffinity="0" group="4" size="0.0040000000000000001 0.0054999999999999997" rgba="0.10000000000000001 0.80000000000000004 0.10000000000000001 1" pos="0 0 0"/>
                            <site name="site_roll_phalanx_2_2" class="b" size="0.001 0.001 0.001" pos="0 -0.0047000000000000002 0"/>
                          </body>
                          <geom name="roll_virtual_2_2" class="b" type="cylinder" contype="0" conaffinity="0" group="4" size="0.0040000000000000001 0.0054999999999999997" rgba="0.10000000000000001 0.80000000000000004 0.10000000000000001 1" pos="0 0 0"/>
                          <site name="site_roll_virtual_2_2" class="b" size="0.001 0.001 0.001" pos="0 -0.0047000000000000002 0"/>
                        </body>
                        <geom name="roll_phalanx_1_2" class="b" type="cylinder" contype="0" conaffinity="0" group="4" size="0.0040000000000000001 0.0054999999999999997" rgba="0.10000000000000001 0.80000000000000004 0.10000000000000001 1" pos="0 0 0"/>
                        <site name="site_roll_phalanx_1_2" class="b" size="0.001 0.001 0.001" pos="0 -0.0047000000000000002 0"/>
                      </body>
                      <geom name="roll_virtual_1_2" class="b" type="cylinder" contype="0" conaffinity="0" group="4" size="0.0040000000000000001 0.0054999999999999997" rgba="0.10000000000000001 0.80000000000000004 0.10000000000000001 1" pos="0 0 0"/>
                      <site name="site_roll_virtual_1_2" class="b" size="0.001 0.001 0.001" pos="0 -0.0047000000000000002 0"/>
                    </body>
                    <body name="virtual_1_3" pos="0.0251205 0 0" quat="0.99680500000000005 0 0 0.079871200000000003">
                      <inertial pos="0 0 0" mass="9.9999999999999995e-07" diaginertia="9.9999999999999995e-07 9.9999999999999995e-07 9.9999999999999995e-07"/>
                      <joint name="heel_phalanx_3_to_virtual_1_3" class="b" pos="0 0 0" axis="0 0 1"/>
                      <body name="phalanx_1_3" pos="0.014 0 0">
                        <inertial pos="0.0062735100000000004 -0.00081271999999999996 8.0566200000000001e-05" quat="0 0.70710700000000004 0 0.70710700000000004" mass="0.0069452999999999997" diaginertia="7.2126499999999997e-07 6.6877600000000003e-07 1.8386400000000001e-07"/>
                        <joint name="virtual_1_3_to_phalanx_1_3" class="b" pos="0 0 0" axis="0 0 1"/>
                        <geom name="unnamed_geom_49_coll" class="b" type="mesh" contype="1" conaffinity="2" group="1" rgba="0.29999999999999999 0.29999999999999999 0.29999999999999999 1" mesh="phalanx_softfoot_size_m"/>
                        <geom name="unnamed_geom_49_vis" class="visual" type="mesh" mesh="phalanx_softfoot_size_m" material="prosthesis_material"/>
                        <body name="virtual_2_3" pos="0.012999999999999999 0 0">
                          <inertial pos="0 0 0" mass="9.9999999999999995e-07" diaginertia="9.9999999999999995e-07 9.9999999999999995e-07 9.9999999999999995e-07"/>
                          <joint name="phalanx_1_3_to_virtual_2_3" class="b" pos="0 0 0" axis="0 0 1"/>
                          <body name="phalanx_2_3" pos="0.014 0 0">
                            <inertial pos="0.0062735100000000004 -0.00081271999999999996 8.0566200000000001e-05" quat="0 0.70710700000000004 0 0.70710700000000004" mass="0.0069452999999999997" diaginertia="7.2126499999999997e-07 6.6877600000000003e-07 1.8386400000000001e-07"/>
                            <joint name="virtual_2_3_to_phalanx_2_3" class="b" pos="0 0 0" axis="0 0 1"/>
                            <geom name="unnamed_geom_50_coll" class="b" type="mesh" contype="1" conaffinity="2" group="1" rgba="0.29999999999999999 0.29999999999999999 0.29999999999999999 1" mesh="phalanx_softfoot_size_m"/>
                            <geom name="unnamed_geom_50_vis" class="visual" type="mesh" mesh="phalanx_softfoot_size_m" material="prosthesis_material"/>
                            <body name="virtual_3_3" pos="0.012999999999999999 0 0">
                              <inertial pos="0 0 0" mass="9.9999999999999995e-07" diaginertia="9.9999999999999995e-07 9.9999999999999995e-07 9.9999999999999995e-07"/>
                              <joint name="phalanx_2_3_to_virtual_3_3" class="b" pos="0 0 0" axis="0 0 1"/>
                              <body name="phalanx_3_3" pos="0.014 0 0">
                                <inertial pos="0.0062735100000000004 -0.00081271999999999996 8.0566200000000001e-05" quat="0 0.70710700000000004 0 0.70710700000000004" mass="0.0069452999999999997" diaginertia="7.2126499999999997e-07 6.6877600000000003e-07 1.8386400000000001e-07"/>
                                <joint name="virtual_3_3_to_phalanx_3_3" class="b" pos="0 0 0" axis="0 0 1"/>
                                <geom name="unnamed_geom_51_coll" class="b" type="mesh" contype="1" conaffinity="2" group="1" rgba="0.29999999999999999 0.29999999999999999 0.29999999999999999 1" mesh="phalanx_softfoot_size_m"/>
                                <geom name="unnamed_geom_51_vis" class="visual" type="mesh" mesh="phalanx_softfoot_size_m" material="prosthesis_material"/>
                                <body name="virtual_4_3" pos="0.012999999999999999 0 0">
                                  <inertial pos="0 0 0" mass="9.9999999999999995e-07" diaginertia="9.9999999999999995e-07 9.9999999999999995e-07 9.9999999999999995e-07"/>
                                  <joint name="phalanx_3_3_to_virtual_4_3" class="b" pos="0 0 0" axis="0 0 1"/>
                                  <body name="reverse_phalanx_3" pos="0.014 0 0" quat="0.99780500000000005 0 0 -0.066227400000000006">
                                    <inertial pos="0.0071278000000000001 0.000123001 7.7890899999999997e-05" quat="0.70710700000000004 0 0 0.70710700000000004" mass="0.0070074899999999999" diaginertia="2.2284600000000001e-07 2.2284600000000001e-07 2.2284600000000001e-07"/>
                                    <joint name="virtual_4_3_to_reverse_phalanx_3" class="b" pos="0 0 0" axis="0 0 1"/>
                                    <geom name="unnamed_geom_52_coll" class="b" type="mesh" contype="1" conaffinity="8" group="1" rgba="0.29999999999999999 0.29999999999999999 0.29999999999999999 1" mesh="phalanx_softfoot_size_reverse"/>
                                    <geom name="unnamed_geom_52_vis" class="visual" type="mesh" mesh="phalanx_softfoot_size_reverse" material="prosthesis_material"/>
                                    <body name="virtual_5_3" pos="0.015132700000000001 0 0" quat="0.99780500000000005 0 0 0.066227400000000006">
                                      <inertial pos="0 0 0" mass="9.9999999999999995e-07" diaginertia="9.9999999999999995e-07 9.9999999999999995e-07 9.9999999999999995e-07"/>
                                      <joint name="reverse_phalanx_3_to_virtual_5_3" class="b" pos="0 0 0" axis="0 0 1" range="-0.15707963267948966 0.78539816339744828"/>
                                      <body name="rollover_phalanx_3" pos="0.014 0 0" quat="0.99748400000000004 0 0 0.070888800000000002">
                                        <inertial pos="0.0071752400000000003 0.0022867999999999999 -1.01402e-05" quat="0.70710700000000004 0.70710700000000004 0 0" mass="0.014041700000000001" diaginertia="0.0021245399999999998 0.0021245399999999998 0.0021245399999999998"/>
                                        <joint name="virtual_5_3_to_rollover_phalanx_3" class="b" pos="0 0 0" axis="0 0 1" range="-0.15707963267948966 0.78539816339744828"/>
                                        <geom name="unnamed_geom_53_coll" class="b" type="mesh" contype="1" conaffinity="8" group="1" rgba="0.90000000000000002 0.90000000000000002 0.90000000000000002 1" mesh="phalanx_softfoot_roll"/>
                                        <geom name="unnamed_geom_53_vis" class="visual" type="mesh" mesh="phalanx_softfoot_roll" material="prosthesis_material"/>
                                        <body name="virtual_6_3" pos="0.014142099999999999 0 0" quat="0.99748400000000004 0 0 -0.070888800000000002">
                                          <inertial pos="0 0 0" mass="9.9999999999999995e-07" diaginertia="9.9999999999999995e-07 9.9999999999999995e-07 9.9999999999999995e-07"/>
                                          <joint name="rollover_phalanx_3_to_virtual_6_3" class="b" pos="0 0 0" axis="0 0 1"/>
                                          <body name="phalanx_4_3" pos="0.014 0 0">
                                            <inertial pos="0.0062735100000000004 -0.00081271999999999996 8.0566200000000001e-05" quat="0 0.70710700000000004 0 0.70710700000000004" mass="0.0069452999999999997" diaginertia="7.2126499999999997e-07 6.6877600000000003e-07 1.8386400000000001e-07"/>
                                            <joint name="virtual_6_3_to_phalanx_4_3" class="b" pos="0 0 0" axis="0 0 1"/>
                                            <geom name="unnamed_geom_54_coll" class="b" type="mesh" contype="1" conaffinity="2" group="1" rgba="0.29999999999999999 0.29999999999999999 0.29999999999999999 1" mesh="phalanx_softfoot_size_m"/>
                                            <geom name="unnamed_geom_54_vis" class="visual" type="mesh" mesh="phalanx_softfoot_size_m" material="prosthesis_material"/>
                                            <body name="virtual_7_3" pos="0.012999999999999999 0 0">
                                              <inertial pos="0 0 0" mass="9.9999999999999995e-07" diaginertia="9.9999999999999995e-07 9.9999999999999995e-07 9.9999999999999995e-07"/>
                                              <joint name="phalanx_4_3_to_virtual_7_3" class="b" pos="0 0 0" axis="0 0 1"/>
                                              <body name="distal_phalanx_3" pos="0.014 0 0">
                                                <inertial pos="0.0036580200000000001 -0.00070785200000000003 0.000211358" quat="0.100463 0.69993399999999995 -0.100463 0.69993399999999995" mass="0.0052713899999999999" diaginertia="2.4732799999999998e-07 2.26785e-07 1.27455e-07"/>
                                                <joint name="virtual_7_3_to_distal_phalanx_3" class="b" pos="0 0 0" axis="0 0 1"/>
                                                <geom name="unnamed_geom_55_coll" class="b" type="mesh" contype="1" conaffinity="2" group="1" rgba="0.90000000000000002 0.90000000000000002 0.90000000000000002 1" mesh="phalanx_softfoot_distal"/>
                                                <geom name="unnamed_geom_55_vis" class="visual" type="mesh" mesh="phalanx_softfoot_distal" material="prosthesis_material"/>
                                                <geom name="roll_distal_phalanx_3" class="b" type="cylinder" contype="0" conaffinity="0" group="4" size="0.0040000000000000001 0.0054999999999999997" rgba="0.10000000000000001 0.80000000000000004 0.10000000000000001 1" pos="0 0 0"/>
                                                <site name="site_roll_distal_phalanx_3" class="b" size="0.001 0.001 0.001" pos="0 -0.0047000000000000002 0"/>
                                                <site name="site_roll_distal_phalanx_3_extreme" class="b" size="0.001 0.001 0.001" pos="0.012999999999999999 -0.0047000000000000002 0"/>
                                              </body>
                                              <geom name="roll_virtual_7_3" class="b" type="cylinder" contype="0" conaffinity="0" group="4" size="0.0040000000000000001 0.0054999999999999997" rgba="0.10000000000000001 0.80000000000000004 0.10000000000000001 1" pos="0 0 0"/>
                                              <site name="site_roll_virtual_7_3" class="b" size="0.001 0.001 0.001" pos="0 -0.0047000000000000002 0"/>
                                            </body>
                                            <geom name="roll_phalanx_4_3" class="b" type="cylinder" contype="0" conaffinity="0" group="4" size="0.0040000000000000001 0.0054999999999999997" rgba="0.10000000000000001 0.80000000000000004 0.10000000000000001 1" pos="0 0 0"/>
                                            <site name="site_roll_phalanx_4_3" class="b" size="0.001 0.001 0.001" pos="0 -0.0047000000000000002 0"/>
                                          </body>
                                          <geom name="roll_virtual_6_3" class="b" type="cylinder" contype="0" conaffinity="0" group="4" size="0.0040000000000000001 0.0054999999999999997" rgba="0.10000000000000001 0.80000000000000004 0.10000000000000001 1" pos="0 0 0"/>
                                          <site name="site_roll_virtual_6_3" class="b" size="0.001 0.001 0.001" pos="0 -0.0047000000000000002 0"/>
                                        </body>
                                        <geom name="roll_rollover_phalanx_3" class="b" type="cylinder" contype="0" conaffinity="0" group="4" size="0.0040000000000000001 0.0054999999999999997" rgba="0.10000000000000001 0.80000000000000004 0.10000000000000001 1" pos="0 0 0"/>
                                        <site name="site_roll_rollover_phalanx_3" class="b" size="0.001 0.001 0.001" pos="0 0.0047000000000000002 0"/>
                                      </body>
                                      <geom name="roll_virtual_5_3" class="b" type="cylinder" contype="0" conaffinity="0" group="4" size="0.0040000000000000001 0.0054999999999999997" rgba="0.10000000000000001 0.80000000000000004 0.10000000000000001 1" pos="0 0 0"/>
                                      <site name="site_roll_virtual_5_3" class="b" size="0.001 0.001 0.001" pos="0 0.0047000000000000002 0"/>
                                    </body>
                                    <geom name="roll_reverse_phalanx_3" class="b" type="cylinder" contype="0" conaffinity="0" group="4" size="0.0040000000000000001 0.0054999999999999997" rgba="0.10000000000000001 0.80000000000000004 0.10000000000000001 1" pos="0 0 0"/>
                                    <site name="site_roll_reverse_phalanx_3" class="b" size="0.001 0.001 0.001" pos="0 -0.0047000000000000002 0"/>
                                  </body>
                                  <geom name="roll_virtual_4_3" class="b" type="cylinder" contype="0" conaffinity="0" group="4" size="0.0040000000000000001 0.0054999999999999997" rgba="0.10000000000000001 0.80000000000000004 0.10000000000000001 1" pos="0 0 0"/>
                                  <site name="site_roll_virtual_4_3" class="b" size="0.001 0.001 0.001" pos="0 -0.0047000000000000002 0"/>
                                </body>
                                <geom name="roll_phalanx_3_3" class="b" type="cylinder" contype="0" conaffinity="0" group="4" size="0.0040000000000000001 0.0054999999999999997" rgba="0.10000000000000001 0.80000000000000004 0.10000000000000001 1" pos="0 0 0"/>
                                <site name="site_roll_phalanx_3_3" class="b" size="0.001 0.001 0.001" pos="0 -0.0047000000000000002 0"/>
                              </body>
                              <geom name="roll_virtual_3_3" class="b" type="cylinder" contype="0" conaffinity="0" group="4" size="0.0040000000000000001 0.0054999999999999997" rgba="0.10000000000000001 0.80000000000000004 0.10000000000000001 1" pos="0 0 0"/>
                              <site name="site_roll_virtual_3_3" class="b" size="0.001 0.001 0.001" pos="0 -0.0047000000000000002 0"/>
                            </body>
                            <geom name="roll_phalanx_2_3" class="b" type="cylinder" contype="0" conaffinity="0" group="4" size="0.0040000000000000001 0.0054999999999999997" rgba="0.10000000000000001 0.80000000000000004 0.10000000000000001 1" pos="0 0 0"/>
                            <site name="site_roll_phalanx_2_3" class="b" size="0.001 0.001 0.001" pos="0 -0.0047000000000000002 0"/>
                          </body>
                          <geom name="roll_virtual_2_3" class="b" type="cylinder" contype="0" conaffinity="0" group="4" size="0.0040000000000000001 0.0054999999999999997" rgba="0.10000000000000001 0.80000000000000004 0.10000000000000001 1" pos="0 0 0"/>
                          <site name="site_roll_virtual_2_3" class="b" size="0.001 0.001 0.001" pos="0 -0.0047000000000000002 0"/>
                        </body>
                        <geom name="roll_phalanx_1_3" class="b" type="cylinder" contype="0" conaffinity="0" group="4" size="0.0040000000000000001 0.0054999999999999997" rgba="0.10000000000000001 0.80000000000000004 0.10000000000000001 1" pos="0 0 0"/>
                        <site name="site_roll_phalanx_1_3" class="b" size="0.001 0.001 0.001" pos="0 -0.0047000000000000002 0"/>
                      </body>
                      <geom name="roll_virtual_1_3" class="b" type="cylinder" contype="0" conaffinity="0" group="4" size="0.0040000000000000001 0.0054999999999999997" rgba="0.10000000000000001 0.80000000000000004 0.10000000000000001 1" pos="0 0 0"/>
                      <site name="site_roll_virtual_1_3" class="b" size="0.001 0.001 0.001" pos="0 -0.0047000000000000002 0"/>
                    </body>
                    <body name="virtual_1_4" pos="0.0251205 0 0.016" quat="0.99680500000000005 0 0 0.079871200000000003">
                      <inertial pos="0 0 0" mass="9.9999999999999995e-07" diaginertia="9.9999999999999995e-07 9.9999999999999995e-07 9.9999999999999995e-07"/>
                      <joint name="heel_phalanx_4_to_virtual_1_4" class="b" pos="0 0 0" axis="0 0 1"/>
                      <body name="phalanx_1_4" pos="0.014 0 0">
                        <inertial pos="0.0062735100000000004 -0.00081271999999999996 8.0566200000000001e-05" quat="0 0.70710700000000004 0 0.70710700000000004" mass="0.0069452999999999997" diaginertia="7.2126499999999997e-07 6.6877600000000003e-07 1.8386400000000001e-07"/>
                        <joint name="virtual_1_4_to_phalanx_1_4" class="b" pos="0 0 0" axis="0 0 1"/>
                        <geom name="unnamed_geom_70_coll" class="b" type="mesh" contype="1" conaffinity="2" group="1" rgba="0.29999999999999999 0.29999999999999999 0.29999999999999999 1" mesh="phalanx_softfoot_size_m"/>
                        <geom name="unnamed_geom_70_vis" class="visual" type="mesh" mesh="phalanx_softfoot_size_m" material="prosthesis_material"/>
                        <body name="virtual_2_4" pos="0.012999999999999999 0 0">
                          <inertial pos="0 0 0" mass="9.9999999999999995e-07" diaginertia="9.9999999999999995e-07 9.9999999999999995e-07 9.9999999999999995e-07"/>
                          <joint name="phalanx_1_4_to_virtual_2_4" class="b" pos="0 0 0" axis="0 0 1"/>
                          <body name="phalanx_2_4" pos="0.014 0 0">
                            <inertial pos="0.0062735100000000004 -0.00081271999999999996 8.0566200000000001e-05" quat="0 0.70710700000000004 0 0.70710700000000004" mass="0.0069452999999999997" diaginertia="7.2126499999999997e-07 6.6877600000000003e-07 1.8386400000000001e-07"/>
                            <joint name="virtual_2_4_to_phalanx_2_4" class="b" pos="0 0 0" axis="0 0 1"/>
                            <geom name="unnamed_geom_71_coll" class="b" type="mesh" contype="1" conaffinity="2" group="1" rgba="0.29999999999999999 0.29999999999999999 0.29999999999999999 1" mesh="phalanx_softfoot_size_m"/>
                            <geom name="unnamed_geom_71_vis" class="visual" type="mesh" mesh="phalanx_softfoot_size_m" material="prosthesis_material"/>
                            <body name="virtual_3_4" pos="0.012999999999999999 0 0">
                              <inertial pos="0 0 0" mass="9.9999999999999995e-07" diaginertia="9.9999999999999995e-07 9.9999999999999995e-07 9.9999999999999995e-07"/>
                              <joint name="phalanx_2_4_to_virtual_3_4" class="b" pos="0 0 0" axis="0 0 1"/>
                              <body name="phalanx_3_4" pos="0.014 0 0">
                                <inertial pos="0.0062735100000000004 -0.00081271999999999996 8.0566200000000001e-05" quat="0 0.70710700000000004 0 0.70710700000000004" mass="0.0069452999999999997" diaginertia="7.2126499999999997e-07 6.6877600000000003e-07 1.8386400000000001e-07"/>
                                <joint name="virtual_3_4_to_phalanx_3_4" class="b" pos="0 0 0" axis="0 0 1"/>
                                <geom name="unnamed_geom_72_coll" class="b" type="mesh" contype="1" conaffinity="2" group="1" rgba="0.29999999999999999 0.29999999999999999 0.29999999999999999 1" mesh="phalanx_softfoot_size_m"/>
                                <geom name="unnamed_geom_72_vis" class="visual" type="mesh" mesh="phalanx_softfoot_size_m" material="prosthesis_material"/>
                                <body name="virtual_4_4" pos="0.012999999999999999 0 0">
                                  <inertial pos="0 0 0" mass="9.9999999999999995e-07" diaginertia="9.9999999999999995e-07 9.9999999999999995e-07 9.9999999999999995e-07"/>
                                  <joint name="phalanx_3_4_to_virtual_4_4" class="b" pos="0 0 0" axis="0 0 1"/>
                                  <body name="reverse_phalanx_4" pos="0.014 0 0" quat="0.99780500000000005 0 0 -0.066227400000000006">
                                    <inertial pos="0.0071278000000000001 0.000123001 7.7890899999999997e-05" quat="0.70710700000000004 0 0 0.70710700000000004" mass="0.0070074899999999999" diaginertia="2.2284600000000001e-07 2.2284600000000001e-07 2.2284600000000001e-07"/>
                                    <joint name="virtual_4_4_to_reverse_phalanx_4" class="b" pos="0 0 0" axis="0 0 1"/>
                                    <geom name="unnamed_geom_73_coll" class="b" type="mesh" contype="1" conaffinity="8" group="1" rgba="0.29999999999999999 0.29999999999999999 0.29999999999999999 1" mesh="phalanx_softfoot_size_reverse"/>
                                    <geom name="unnamed_geom_73_vis" class="visual" type="mesh" mesh="phalanx_softfoot_size_reverse" material="prosthesis_material"/>
                                    <body name="virtual_5_4" pos="0.015132700000000001 0 0" quat="0.99780500000000005 0 0 0.066227400000000006">
                                      <inertial pos="0 0 0" mass="9.9999999999999995e-07" diaginertia="9.9999999999999995e-07 9.9999999999999995e-07 9.9999999999999995e-07"/>
                                      <joint name="reverse_phalanx_4_to_virtual_5_4" class="b" pos="0 0 0" axis="0 0 1" range="-0.15707963267948966 0.78539816339744828"/>
                                      <body name="rollover_phalanx_4" pos="0.014 0 0" quat="0.99748400000000004 0 0 0.070888800000000002">
                                        <inertial pos="0.0071752400000000003 0.0022867999999999999 -1.01402e-05" quat="0.70710700000000004 0.70710700000000004 0 0" mass="0.014041700000000001" diaginertia="0.0021245399999999998 0.0021245399999999998 0.0021245399999999998"/>
                                        <joint name="virtual_5_4_to_rollover_phalanx_4" class="b" pos="0 0 0" axis="0 0 1" range="-0.15707963267948966 0.78539816339744828"/>
                                        <geom name="unnamed_geom_74_coll" class="b" type="mesh" contype="1" conaffinity="8" group="1" rgba="0.90000000000000002 0.90000000000000002 0.90000000000000002 1" mesh="phalanx_softfoot_roll"/>
                                        <geom name="unnamed_geom_74_vis" class="visual" type="mesh" mesh="phalanx_softfoot_roll" material="prosthesis_material"/>
                                        <body name="virtual_6_4" pos="0.014142099999999999 0 0" quat="0.99748400000000004 0 0 -0.070888800000000002">
                                          <inertial pos="0 0 0" mass="9.9999999999999995e-07" diaginertia="9.9999999999999995e-07 9.9999999999999995e-07 9.9999999999999995e-07"/>
                                          <joint name="rollover_phalanx_4_to_virtual_6_4" class="b" pos="0 0 0" axis="0 0 1"/>
                                          <body name="phalanx_4_4" pos="0.014 0 0">
                                            <inertial pos="0.0062735100000000004 -0.00081271999999999996 8.0566200000000001e-05" quat="0 0.70710700000000004 0 0.70710700000000004" mass="0.0069452999999999997" diaginertia="7.2126499999999997e-07 6.6877600000000003e-07 1.8386400000000001e-07"/>
                                            <joint name="virtual_6_4_to_phalanx_4_4" class="b" pos="0 0 0" axis="0 0 1"/>
                                            <geom name="unnamed_geom_75_coll" class="b" type="mesh" contype="1" conaffinity="2" group="1" rgba="0.29999999999999999 0.29999999999999999 0.29999999999999999 1" mesh="phalanx_softfoot_size_m"/>
                                            <geom name="unnamed_geom_75_vis" class="visual" type="mesh" mesh="phalanx_softfoot_size_m" material="prosthesis_material"/>
                                            <body name="virtual_7_4" pos="0.012999999999999999 0 0">
                                              <inertial pos="0 0 0" mass="9.9999999999999995e-07" diaginertia="9.9999999999999995e-07 9.9999999999999995e-07 9.9999999999999995e-07"/>
                                              <joint name="phalanx_4_4_to_virtual_7_4" class="b" pos="0 0 0" axis="0 0 1"/>
                                              <body name="distal_phalanx_4" pos="0.014 0 0">
                                                <inertial pos="0.0036580200000000001 -0.00070785200000000003 0.000211358" quat="0.100463 0.69993399999999995 -0.100463 0.69993399999999995" mass="0.0052713899999999999" diaginertia="2.4732799999999998e-07 2.26785e-07 1.27455e-07"/>
                                                <joint name="virtual_7_4_to_distal_phalanx_4" class="b" pos="0 0 0" axis="0 0 1"/>
                                                <geom name="unnamed_geom_76_coll" class="b" type="mesh" contype="1" conaffinity="2" group="1" rgba="0.90000000000000002 0.90000000000000002 0.90000000000000002 1" mesh="phalanx_softfoot_distal"/>
                                                <geom name="unnamed_geom_76_vis" class="visual" type="mesh" mesh="phalanx_softfoot_distal" material="prosthesis_material"/>
                                                <geom name="roll_distal_phalanx_4" class="b" type="cylinder" contype="0" conaffinity="0" group="4" size="0.0040000000000000001 0.0054999999999999997" rgba="0.10000000000000001 0.80000000000000004 0.10000000000000001 1" pos="0 0 0"/>
                                                <site name="site_roll_distal_phalanx_4" class="b" size="0.001 0.001 0.001" pos="0 -0.0047000000000000002 0"/>
                                                <site name="site_roll_distal_phalanx_4_extreme" class="b" size="0.001 0.001 0.001" pos="0.012999999999999999 -0.0047000000000000002 0"/>
                                              </body>
                                              <geom name="roll_virtual_7_4" class="b" type="cylinder" contype="0" conaffinity="0" group="4" size="0.0040000000000000001 0.0054999999999999997" rgba="0.10000000000000001 0.80000000000000004 0.10000000000000001 1" pos="0 0 0"/>
                                              <site name="site_roll_virtual_7_4" class="b" size="0.001 0.001 0.001" pos="0 -0.0047000000000000002 0"/>
                                            </body>
                                            <geom name="roll_phalanx_4_4" class="b" type="cylinder" contype="0" conaffinity="0" group="4" size="0.0040000000000000001 0.0054999999999999997" rgba="0.10000000000000001 0.80000000000000004 0.10000000000000001 1" pos="0 0 0"/>
                                            <site name="site_roll_phalanx_4_4" class="b" size="0.001 0.001 0.001" pos="0 -0.0047000000000000002 0"/>
                                          </body>
                                          <geom name="roll_virtual_6_4" class="b" type="cylinder" contype="0" conaffinity="0" group="4" size="0.0040000000000000001 0.0054999999999999997" rgba="0.10000000000000001 0.80000000000000004 0.10000000000000001 1" pos="0 0 0"/>
                                          <site name="site_roll_virtual_6_4" class="b" size="0.001 0.001 0.001" pos="0 -0.0047000000000000002 0"/>
                                        </body>
                                        <geom name="roll_rollover_phalanx_4" class="b" type="cylinder" contype="0" conaffinity="0" group="4" size="0.0040000000000000001 0.0054999999999999997" rgba="0.10000000000000001 0.80000000000000004 0.10000000000000001 1" pos="0 0 0"/>
                                        <site name="site_roll_rollover_phalanx_4" class="b" size="0.001 0.001 0.001" pos="0 0.0047000000000000002 0"/>
                                      </body>
                                      <geom name="roll_virtual_5_4" class="b" type="cylinder" contype="0" conaffinity="0" group="4" size="0.0040000000000000001 0.0054999999999999997" rgba="0.10000000000000001 0.80000000000000004 0.10000000000000001 1" pos="0 0 0"/>
                                      <site name="site_roll_virtual_5_4" class="b" size="0.001 0.001 0.001" pos="0 0.0047000000000000002 0"/>
                                    </body>
                                    <geom name="roll_reverse_phalanx_4" class="b" type="cylinder" contype="0" conaffinity="0" group="4" size="0.0040000000000000001 0.0054999999999999997" rgba="0.10000000000000001 0.80000000000000004 0.10000000000000001 1" pos="0 0 0"/>
                                    <site name="site_roll_reverse_phalanx_4" class="b" size="0.001 0.001 0.001" pos="0 -0.0047000000000000002 0"/>
                                  </body>
                                  <geom name="roll_virtual_4_4" class="b" type="cylinder" contype="0" conaffinity="0" group="4" size="0.0040000000000000001 0.0054999999999999997" rgba="0.10000000000000001 0.80000000000000004 0.10000000000000001 1" pos="0 0 0"/>
                                  <site name="site_roll_virtual_4_4" class="b" size="0.001 0.001 0.001" pos="0 -0.0047000000000000002 0"/>
                                </body>
                                <geom name="roll_phalanx_3_4" class="b" type="cylinder" contype="0" conaffinity="0" group="4" size="0.0040000000000000001 0.0054999999999999997" rgba="0.10000000000000001 0.80000000000000004 0.10000000000000001 1" pos="0 0 0"/>
                                <site name="site_roll_phalanx_3_4" class="b" size="0.001 0.001 0.001" pos="0 -0.0047000000000000002 0"/>
                              </body>
                              <geom name="roll_virtual_3_4" class="b" type="cylinder" contype="0" conaffinity="0" group="4" size="0.0040000000000000001 0.0054999999999999997" rgba="0.10000000000000001 0.80000000000000004 0.10000000000000001 1" pos="0 0 0"/>
                              <site name="site_roll_virtual_3_4" class="b" size="0.001 0.001 0.001" pos="0 -0.0047000000000000002 0"/>
                            </body>
                            <geom name="roll_phalanx_2_4" class="b" type="cylinder" contype="0" conaffinity="0" group="4" size="0.0040000000000000001 0.0054999999999999997" rgba="0.10000000000000001 0.80000000000000004 0.10000000000000001 1" pos="0 0 0"/>
                            <site name="site_roll_phalanx_2_4" class="b" size="0.001 0.001 0.001" pos="0 -0.0047000000000000002 0"/>
                          </body>
                          <geom name="roll_virtual_2_4" class="b" type="cylinder" contype="0" conaffinity="0" group="4" size="0.0040000000000000001 0.0054999999999999997" rgba="0.10000000000000001 0.80000000000000004 0.10000000000000001 1" pos="0 0 0"/>
                          <site name="site_roll_virtual_2_4" class="b" size="0.001 0.001 0.001" pos="0 -0.0047000000000000002 0"/>
                        </body>
                        <geom name="roll_phalanx_1_4" class="b" type="cylinder" contype="0" conaffinity="0" group="4" size="0.0040000000000000001 0.0054999999999999997" rgba="0.10000000000000001 0.80000000000000004 0.10000000000000001 1" pos="0 0 0"/>
                        <site name="site_roll_phalanx_1_4" class="b" size="0.001 0.001 0.001" pos="0 -0.0047000000000000002 0"/>
                      </body>
                      <geom name="roll_virtual_1_4" class="b" type="cylinder" contype="0" conaffinity="0" group="4" size="0.0040000000000000001 0.0054999999999999997" rgba="0.10000000000000001 0.80000000000000004 0.10000000000000001 1" pos="0 0 0"/>
                      <site name="site_roll_virtual_1_4" class="b" size="0.001 0.001 0.001" pos="0 -0.0047000000000000002 0"/>
                    </body>
                    <body name="virtual_1_5" pos="0.0251205 0 0.032000000000000001" quat="0.99680500000000005 0 0 0.079871200000000003">
                      <inertial pos="0 0 0" mass="9.9999999999999995e-07" diaginertia="9.9999999999999995e-07 9.9999999999999995e-07 9.9999999999999995e-07"/>
                      <joint name="heel_phalanx_5_to_virtual_1_5" class="b" pos="0 0 0" axis="0 0 1"/>
                      <body name="phalanx_1_5" pos="0.014 0 0">
                        <inertial pos="0.0062735100000000004 -0.00081271999999999996 8.0566200000000001e-05" quat="0 0.70710700000000004 0 0.70710700000000004" mass="0.0069452999999999997" diaginertia="7.2126499999999997e-07 6.6877600000000003e-07 1.8386400000000001e-07"/>
                        <joint name="virtual_1_5_to_phalanx_1_5" class="b" pos="0 0 0" axis="0 0 1"/>
                        <geom name="unnamed_geom_91_coll" class="b" type="mesh" contype="1" conaffinity="2" group="1" rgba="0.29999999999999999 0.29999999999999999 0.29999999999999999 1" mesh="phalanx_softfoot_size_m"/>
                        <geom name="unnamed_geom_91_vis" class="visual" type="mesh" mesh="phalanx_softfoot_size_m" material="prosthesis_material"/>
                        <body name="virtual_2_5" pos="0.012999999999999999 0 0">
                          <inertial pos="0 0 0" mass="9.9999999999999995e-07" diaginertia="9.9999999999999995e-07 9.9999999999999995e-07 9.9999999999999995e-07"/>
                          <joint name="phalanx_1_5_to_virtual_2_5" class="b" pos="0 0 0" axis="0 0 1"/>
                          <body name="phalanx_2_5" pos="0.014 0 0">
                            <inertial pos="0.0062735100000000004 -0.00081271999999999996 8.0566200000000001e-05" quat="0 0.70710700000000004 0 0.70710700000000004" mass="0.0069452999999999997" diaginertia="7.2126499999999997e-07 6.6877600000000003e-07 1.8386400000000001e-07"/>
                            <joint name="virtual_2_5_to_phalanx_2_5" class="b" pos="0 0 0" axis="0 0 1"/>
                            <geom name="unnamed_geom_92_coll" class="b" type="mesh" contype="1" conaffinity="2" group="1" rgba="0.29999999999999999 0.29999999999999999 0.29999999999999999 1" mesh="phalanx_softfoot_size_m"/>
                            <geom name="unnamed_geom_92_vis" class="visual" type="mesh" mesh="phalanx_softfoot_size_m" material="prosthesis_material"/>
                            <body name="virtual_3_5" pos="0.012999999999999999 0 0">
                              <inertial pos="0 0 0" mass="9.9999999999999995e-07" diaginertia="9.9999999999999995e-07 9.9999999999999995e-07 9.9999999999999995e-07"/>
                              <joint name="phalanx_2_5_to_virtual_3_5" class="b" pos="0 0 0" axis="0 0 1"/>
                              <body name="phalanx_3_5" pos="0.014 0 0">
                                <inertial pos="0.0062735100000000004 -0.00081271999999999996 8.0566200000000001e-05" quat="0 0.70710700000000004 0 0.70710700000000004" mass="0.0069452999999999997" diaginertia="7.2126499999999997e-07 6.6877600000000003e-07 1.8386400000000001e-07"/>
                                <joint name="virtual_3_5_to_phalanx_3_5" class="b" pos="0 0 0" axis="0 0 1"/>
                                <geom name="unnamed_geom_93_coll" class="b" type="mesh" contype="1" conaffinity="2" group="1" rgba="0.29999999999999999 0.29999999999999999 0.29999999999999999 1" mesh="phalanx_softfoot_size_m"/>
                                <geom name="unnamed_geom_93_vis" class="visual" type="mesh" mesh="phalanx_softfoot_size_m" material="prosthesis_material"/>
                                <body name="virtual_4_5" pos="0.012999999999999999 0 0">
                                  <inertial pos="0 0 0" mass="9.9999999999999995e-07" diaginertia="9.9999999999999995e-07 9.9999999999999995e-07 9.9999999999999995e-07"/>
                                  <joint name="phalanx_3_5_to_virtual_4_5" class="b" pos="0 0 0" axis="0 0 1"/>
                                  <body name="reverse_phalanx_5" pos="0.014 0 0" quat="0.99780500000000005 0 0 -0.066227400000000006">
                                    <inertial pos="0.0071278000000000001 0.000123001 7.7890899999999997e-05" quat="0.70710700000000004 0 0 0.70710700000000004" mass="0.0070074899999999999" diaginertia="2.2284600000000001e-07 2.2284600000000001e-07 2.2284600000000001e-07"/>
                                    <joint name="virtual_4_5_to_reverse_phalanx_5" class="b" pos="0 0 0" axis="0 0 1"/>
                                    <geom name="unnamed_geom_94_coll" class="b" type="mesh" contype="1" conaffinity="8" group="1" rgba="0.29999999999999999 0.29999999999999999 0.29999999999999999 1" mesh="phalanx_softfoot_size_reverse"/>
                                    <geom name="unnamed_geom_94_vis" class="visual" type="mesh" mesh="phalanx_softfoot_size_reverse" material="prosthesis_material"/>
                                    <body name="virtual_5_5" pos="0.015132700000000001 0 0" quat="0.99780500000000005 0 0 0.066227400000000006">
                                      <inertial pos="0 0 0" mass="9.9999999999999995e-07" diaginertia="9.9999999999999995e-07 9.9999999999999995e-07 9.9999999999999995e-07"/>
                                      <joint name="reverse_phalanx_5_to_virtual_5_5" class="b" pos="0 0 0" axis="0 0 1" range="-0.15707963267948966 0.78539816339744828"/>
                                      <body name="rollover_phalanx_5" pos="0.014 0 0" quat="0.99748400000000004 0 0 0.070888800000000002">
                                        <inertial pos="0.0071752400000000003 0.0022867999999999999 -1.01402e-05" quat="0.70710700000000004 0.70710700000000004 0 0" mass="0.014041700000000001" diaginertia="0.0021245399999999998 0.0021245399999999998 0.0021245399999999998"/>
                                        <joint name="virtual_5_5_to_rollover_phalanx_5" class="b" pos="0 0 0" axis="0 0 1" range="-0.15707963267948966 0.78539816339744828"/>
                                        <geom name="unnamed_geom_95_coll" class="b" type="mesh" contype="1" conaffinity="8" group="1" rgba="0.90000000000000002 0.90000000000000002 0.90000000000000002 1" mesh="phalanx_softfoot_roll"/>
                                        <geom name="unnamed_geom_95_vis" class="visual" type="mesh" mesh="phalanx_softfoot_roll" material="prosthesis_material"/>
                                        <body name="virtual_6_5" pos="0.014142099999999999 0 0" quat="0.99748400000000004 0 0 -0.070888800000000002">
                                          <inertial pos="0 0 0" mass="9.9999999999999995e-07" diaginertia="9.9999999999999995e-07 9.9999999999999995e-07 9.9999999999999995e-07"/>
                                          <joint name="rollover_phalanx_5_to_virtual_6_5" class="b" pos="0 0 0" axis="0 0 1"/>
                                          <body name="phalanx_4_5" pos="0.014 0 0">
                                            <inertial pos="0.0062735100000000004 -0.00081271999999999996 8.0566200000000001e-05" quat="0 0.70710700000000004 0 0.70710700000000004" mass="0.0069452999999999997" diaginertia="7.2126499999999997e-07 6.6877600000000003e-07 1.8386400000000001e-07"/>
                                            <joint name="virtual_6_5_to_phalanx_4_5" class="b" pos="0 0 0" axis="0 0 1"/>
                                            <geom name="unnamed_geom_96_coll" class="b" type="mesh" contype="1" conaffinity="2" group="1" rgba="0.29999999999999999 0.29999999999999999 0.29999999999999999 1" mesh="phalanx_softfoot_size_m"/>
                                            <geom name="unnamed_geom_96_vis" class="visual" type="mesh" mesh="phalanx_softfoot_size_m" material="prosthesis_material"/>
                                            <body name="virtual_7_5" pos="0.012999999999999999 0 0">
                                              <inertial pos="0 0 0" mass="9.9999999999999995e-07" diaginertia="9.9999999999999995e-07 9.9999999999999995e-07 9.9999999999999995e-07"/>
                                              <joint name="phalanx_4_5_to_virtual_7_5" class="b" pos="0 0 0" axis="0 0 1"/>
                                              <body name="distal_phalanx_5" pos="0.014 0 0">
                                                <inertial pos="0.0036580200000000001 -0.00070785200000000003 0.000211358" quat="0.100463 0.69993399999999995 -0.100463 0.69993399999999995" mass="0.0052713899999999999" diaginertia="2.4732799999999998e-07 2.26785e-07 1.27455e-07"/>
                                                <joint name="virtual_7_5_to_distal_phalanx_5" class="b" pos="0 0 0" axis="0 0 1"/>
                                                <geom name="unnamed_geom_97_coll" class="b" type="mesh" contype="1" conaffinity="2" group="1" rgba="0.90000000000000002 0.90000000000000002 0.90000000000000002 1" mesh="phalanx_softfoot_distal"/>
                                                <geom name="unnamed_geom_97_vis" class="visual" type="mesh" mesh="phalanx_softfoot_distal" material="prosthesis_material"/>
                                                <geom name="roll_distal_phalanx_5" class="b" type="cylinder" contype="0" conaffinity="0" group="4" size="0.0040000000000000001 0.0054999999999999997" rgba="0.10000000000000001 0.80000000000000004 0.10000000000000001 1" pos="0 0 0"/>
                                                <site name="site_roll_distal_phalanx_5" class="b" size="0.001 0.001 0.001" pos="0 -0.0047000000000000002 0"/>
                                                <site name="site_roll_distal_phalanx_5_extreme" class="b" size="0.001 0.001 0.001" pos="0.012999999999999999 -0.0047000000000000002 0"/>
                                              </body>
                                              <geom name="roll_virtual_7_5" class="b" type="cylinder" contype="0" conaffinity="0" group="4" size="0.0040000000000000001 0.0054999999999999997" rgba="0.10000000000000001 0.80000000000000004 0.10000000000000001 1" pos="0 0 0"/>
                                              <site name="site_roll_virtual_7_5" class="b" size="0.001 0.001 0.001" pos="0 -0.0047000000000000002 0"/>
                                            </body>
                                            <geom name="roll_phalanx_4_5" class="b" type="cylinder" contype="0" conaffinity="0" group="4" size="0.0040000000000000001 0.0054999999999999997" rgba="0.10000000000000001 0.80000000000000004 0.10000000000000001 1" pos="0 0 0"/>
                                            <site name="site_roll_phalanx_4_5" class="b" size="0.001 0.001 0.001" pos="0 -0.0047000000000000002 0"/>
                                          </body>
                                          <geom name="roll_virtual_6_5" class="b" type="cylinder" contype="0" conaffinity="0" group="4" size="0.0040000000000000001 0.0054999999999999997" rgba="0.10000000000000001 0.80000000000000004 0.10000000000000001 1" pos="0 0 0"/>
                                          <site name="site_roll_virtual_6_5" class="b" size="0.001 0.001 0.001" pos="0 -0.0047000000000000002 0"/>
                                        </body>
                                        <geom name="roll_rollover_phalanx_5" class="b" type="cylinder" contype="0" conaffinity="0" group="4" size="0.0040000000000000001 0.0054999999999999997" rgba="0.10000000000000001 0.80000000000000004 0.10000000000000001 1" pos="0 0 0"/>
                                        <site name="site_roll_rollover_phalanx_5" class="b" size="0.001 0.001 0.001" pos="0 0.0047000000000000002 0"/>
                                      </body>
                                      <geom name="roll_virtual_5_5" class="b" type="cylinder" contype="0" conaffinity="0" group="4" size="0.0040000000000000001 0.0054999999999999997" rgba="0.10000000000000001 0.80000000000000004 0.10000000000000001 1" pos="0 0 0"/>
                                      <site name="site_roll_virtual_5_5" class="b" size="0.001 0.001 0.001" pos="0 0.0047000000000000002 0"/>
                                    </body>
                                    <geom name="roll_reverse_phalanx_5" class="b" type="cylinder" contype="0" conaffinity="0" group="4" size="0.0040000000000000001 0.0054999999999999997" rgba="0.10000000000000001 0.80000000000000004 0.10000000000000001 1" pos="0 0 0"/>
                                    <site name="site_roll_reverse_phalanx_5" class="b" size="0.001 0.001 0.001" pos="0 -0.0047000000000000002 0"/>
                                  </body>
                                  <geom name="roll_virtual_4_5" class="b" type="cylinder" contype="0" conaffinity="0" group="4" size="0.0040000000000000001 0.0054999999999999997" rgba="0.10000000000000001 0.80000000000000004 0.10000000000000001 1" pos="0 0 0"/>
                                  <site name="site_roll_virtual_4_5" class="b" size="0.001 0.001 0.001" pos="0 -0.0047000000000000002 0"/>
                                </body>
                                <geom name="roll_phalanx_3_5" class="b" type="cylinder" contype="0" conaffinity="0" group="4" size="0.0040000000000000001 0.0054999999999999997" rgba="0.10000000000000001 0.80000000000000004 0.10000000000000001 1" pos="0 0 0"/>
                                <site name="site_roll_phalanx_3_5" class="b" size="0.001 0.001 0.001" pos="0 -0.0047000000000000002 0"/>
                              </body>
                              <geom name="roll_virtual_3_5" class="b" type="cylinder" contype="0" conaffinity="0" group="4" size="0.0040000000000000001 0.0054999999999999997" rgba="0.10000000000000001 0.80000000000000004 0.10000000000000001 1" pos="0 0 0"/>
                              <site name="site_roll_virtual_3_5" class="b" size="0.001 0.001 0.001" pos="0 -0.0047000000000000002 0"/>
                            </body>
                            <geom name="roll_phalanx_2_5" class="b" type="cylinder" contype="0" conaffinity="0" group="4" size="0.0040000000000000001 0.0054999999999999997" rgba="0.10000000000000001 0.80000000000000004 0.10000000000000001 1" pos="0 0 0"/>
                            <site name="site_roll_phalanx_2_5" class="b" size="0.001 0.001 0.001" pos="0 -0.0047000000000000002 0"/>
                          </body>
                          <geom name="roll_virtual_2_5" class="b" type="cylinder" contype="0" conaffinity="0" group="4" size="0.0040000000000000001 0.0054999999999999997" rgba="0.10000000000000001 0.80000000000000004 0.10000000000000001 1" pos="0 0 0"/>
                          <site name="site_roll_virtual_2_5" class="b" size="0.001 0.001 0.001" pos="0 -0.0047000000000000002 0"/>
                        </body>
                        <geom name="roll_phalanx_1_5" class="b" type="cylinder" contype="0" conaffinity="0" group="4" size="0.0040000000000000001 0.0054999999999999997" rgba="0.10000000000000001 0.80000000000000004 0.10000000000000001 1" pos="0 0 0"/>
                        <site name="site_roll_phalanx_1_5" class="b" size="0.001 0.001 0.001" pos="0 -0.0047000000000000002 0"/>
                      </body>
                      <geom name="roll_virtual_1_5" class="b" type="cylinder" contype="0" conaffinity="0" group="4" size="0.0040000000000000001 0.0054999999999999997" rgba="0.10000000000000001 0.80000000000000004 0.10000000000000001 1" pos="0 0 0"/>
                      <site name="site_roll_virtual_1_5" class="b" size="0.001 0.001 0.001" pos="0 -0.0047000000000000002 0"/>
                    </body>
                    <site name="site_heel_spring_r" class="b" rgba="0.90000000000000002 0.10000000000000001 0.10000000000000001 0.5" size="0.001 0.001 0.001" pos="0.025999999999999999 0.012500000000000001 0.0074999999999999997"/>
                    <site name="site_heel_spring_l" class="b" rgba="0.90000000000000002 0.10000000000000001 0.10000000000000001 0.5" size="0.001 0.001 0.001" pos="0.025999999999999999 0.012500000000000001 -0.0074999999999999997"/>
                  </body>
                  <body name="frontal_arch" pos="0 -0.027 0" quat="0.96297500000000003 0 0 -0.26959">
                    <inertial pos="0.064867400000000006 -0.0048263999999999998 -0.00207734" quat="0.47717100000000001 0.50193299999999996 0.520424 0.49952999999999997" mass="0.12008000000000001" diaginertia="0.00019423699999999999 0.000180915 1.9264400000000001e-05"/>
                    <joint name="posterior_arch_to_frontal_arch" class="b" pos="0 0 0" axis="0 0 1" stiffness="0" armature="0.01" damping="0.0001"/>
                    <geom name="unnamed_geom_112_coll" class="b" type="mesh" contype="2" conaffinity="2" group="1" rgba="0.29999999999999999 0.29999999999999999 0.29999999999999999 1" mesh="rollover_link_v1_2"/>
                    <geom name="unnamed_geom_112_vis" class="visual" type="mesh" mesh="rollover_link_v1_2" material="prosthesis_material"/>
                  </body>
                  <geom name="roll_posterior_arch" class="b" type="cylinder" contype="0" conaffinity="0" group="4" size="0.0040000000000000001 0.0054999999999999997" rgba="0.10000000000000001 0.80000000000000004 0.10000000000000001 1" pos="0 0 0"/>
                  <site name="site_roll_posterior_arch" class="b" size="0.001 0.001 0.001" pos="0 -0.0047000000000000002 0"/>
                  <site name="site_posterior_spring_r" class="b" size="0.001 0.001 0.001" pos="-0.035641291583283455 -0.05870265500356979 0.004000000000000001"/>
                  <site name="site_posterior_spring_l" class="b" size="0.001 0.001 0.001" pos="-0.035641291583283455 -0.05870265500356979 -0.011000000000000001"/>
                </body>
                <!-- =========== END OF PROSTHESIS DEFINITION =========== -->
              </body>
            </body>
          </body>
        </body>
      </body>
      <body name="torso_link">
        <site name="upper_body_mimic" class="mimic" pos="0.05 0.0 0.3"/>
        <site name="head_mimic" class="mimic" pos="0.0 0.0 0.6"/>
        <inertial pos="0.000489 0.002797 0.20484" quat="0.999989 -0.00130808 -0.00282289 -0.00349105" mass="17.789"
          diaginertia="0.487315 0.409628 0.127837"/>
        <joint name="back_bkz" axis="0 0 1" range="-2.35 2.35"/>
        <geom class="visual" mesh="torso_link"/>
        <geom class="collision" mesh="torso_link"/>
        <geom class="visual" material="white" mesh="logo_link"/>
        <site name="imu" size="0.01" pos="-0.04452 -0.01891 0.27756"/>
        <body name="left_shoulder_pitch_link" pos="0.0055 0.15535 0.42999" quat="0.976296 0.216438 0 0">
          <inertial pos="0.005045 0.053657 -0.015715" quat="0.814858 0.579236 -0.0201072 -0.00936488" mass="1.033"
            diaginertia="0.00129936 0.000987113 0.000858198"/>
          <joint name="l_arm_shy" axis="0 1 0" range="-2.87 2.87"/>
          <geom class="visual" mesh="left_shoulder_pitch_link"/>
          <geom class="collision" mesh="left_shoulder_pitch_link"/>
          <body name="left_shoulder_roll_link" pos="-0.0055 0.0565 -0.0165" quat="0.976296 -0.216438 0 0">
            <site name="left_shoulder_mimic" class="mimic"/>
            <inertial pos="0.000679 0.00115 -0.094076" quat="0.732491 0.00917179 0.0766656 0.676384" mass="0.793"
              diaginertia="0.00170388 0.00158256 0.00100336"/>
            <joint name="l_arm_shx" axis="1 0 0" range="-0.34 3.11"/>
            <geom class="visual" mesh="left_shoulder_roll_link"/>
            <geom class="collision" mesh="left_shoulder_roll_link"/>
            <body name="left_shoulder_yaw_link" pos="0 0 -0.1343">
              <inertial pos="0.01365 0.002767 -0.16266" quat="0.703042 -0.0331229 -0.0473362 0.708798" mass="0.839"
                diaginertia="0.00408038 0.00370367 0.000622687"/>
              <joint name="l_arm_shz" axis="0 0 1" range="-1.3 4.45"/>
              <geom class="visual" mesh="left_shoulder_yaw_link"/>
              <geom class="collision" mesh="left_shoulder_yaw_link"/>
              <body name="left_elbow_link" pos="0.0185 0 -0.198">
                <site name="left_elbow_mimic" class="mimic"/>
                <site name="left_hand_mimic" class="mimic" pos="0.3 0.0 0.0"/>
                <inertial pos="0.15908 -0.000144 -0.015776" quat="0.0765232 0.720327 0.0853116 0.684102" mass="0.669"
                  diaginertia="0.00601829 0.00600579 0.000408305"/>
                <joint name="left_elbow" axis="0 1 0" range="-1.25 2.61"/>
                <geom class="visual" mesh="left_elbow_link"/>
                <geom class="collision" mesh="left_elbow_link"/>
              </body>
            </body>
          </body>
        </body>
        <body name="right_shoulder_pitch_link" pos="0.0055 -0.15535 0.42999" quat="0.976296 -0.216438 0 0">
          <inertial pos="0.005045 -0.053657 -0.015715" quat="0.579236 0.814858 0.00936488 0.0201072" mass="1.033"
            diaginertia="0.00129936 0.000987113 0.000858198"/>
          <joint name="r_arm_shy" axis="0 1 0" range="-2.87 2.87"/>
          <geom class="visual" mesh="right_shoulder_pitch_link"/>
          <geom class="collision" mesh="right_shoulder_pitch_link"/>
          <body name="right_shoulder_roll_link" pos="-0.0055 -0.0565 -0.0165" quat="0.976296 0.216438 0 0">
            <site name="right_shoulder_mimic" class="mimic"/>
            <inertial pos="0.000679 -0.00115 -0.094076" quat="0.676384 0.0766656 0.00917179 0.732491" mass="0.793"
              diaginertia="0.00170388 0.00158256 0.00100336"/>
            <joint name="r_arm_shx" axis="1 0 0" range="-3.11 0.34"/>
            <geom class="visual" mesh="right_shoulder_roll_link"/>
            <geom class="collision" mesh="right_shoulder_roll_link"/>
            <body name="right_shoulder_yaw_link" pos="0 0 -0.1343">
              <inertial pos="0.01365 -0.002767 -0.16266" quat="0.708798 -0.0473362 -0.0331229 0.703042" mass="0.839"
                diaginertia="0.00408038 0.00370367 0.000622687"/>
              <joint name="r_arm_shz" axis="0 0 1" range="-4.45 1.3"/>
              <geom class="visual" mesh="right_shoulder_yaw_link"/>
              <geom class="collision" mesh="right_shoulder_yaw_link"/>
              <body name="right_elbow_link" pos="0.0185 0 -0.198">
                <site name="right_elbow_mimic" class="mimic"/>
                <site name="right_hand_mimic" class="mimic" pos="0.3 0.0 0.0"/>
                <inertial pos="0.15908 0.000144 -0.015776" quat="-0.0765232 0.720327 -0.0853116 0.684102" mass="0.669"
                  diaginertia="0.00601829 0.00600579 0.000408305"/>
                <joint name="right_elbow" axis="0 1 0" range="-1.25 2.61"/>
                <geom class="visual" mesh="right_elbow_link"/>
                <geom class="collision" mesh="right_elbow_link"/>
              </body>
            </body>
          </body>
        </body>
      </body>
    </body>
  </worldbody>

<actuator>
    <motor class="h1" name="hip_rotation_l_actuator" joint="hip_rotation_l" ctrlrange="-200 200"/>
    <motor class="h1" name="hip_adduction_l_actuator" joint="hip_adduction_l" ctrlrange="-200 200"/>
    <motor class="h1" name="hip_flexion_l_actuator" joint="hip_flexion_l" ctrlrange="-200 200"/>
    <motor class="h1" name="knee_angle_l_actuator" joint="knee_angle_l" ctrlrange="-300 300"/>
    <motor class="h1" name="ankle_angle_l_actuator" joint="ankle_angle_l" ctrlrange="-40 40"/>
    <motor class="h1" name="hip_rotation_r_actuator" joint="hip_rotation_r" ctrlrange="-200 200"/>
    <motor class="h1" name="hip_adduction_r_actuator" joint="hip_adduction_r" ctrlrange="-200 200"/>
    <motor class="h1" name="hip_flexion_r_actuator" joint="hip_flexion_r" ctrlrange="-200 200"/>
    <motor class="h1" name="knee_angle_r_actuator" joint="knee_angle_r" ctrlrange="-300 300"/>
    <motor class="h1" name="ankle_angle_r_actuator" joint="ankle_angle_r" ctrlrange="-40 40"/>
    <motor class="h1" name="back_bkz_actuator" joint="back_bkz" ctrlrange="-200 200"/>
    <motor class="h1" name="l_arm_shy_actuator" joint="l_arm_shy" ctrlrange="-40 40"/>
    <motor class="h1" name="l_arm_shx_actuator" joint="l_arm_shx" ctrlrange="-40 40"/>
    <motor class="h1" name="l_arm_shz_actuator" joint="l_arm_shz" ctrlrange="-18 18"/>
    <motor class="h1" name="left_elbow_actuator" joint="left_elbow" ctrlrange="-18 18"/>
    <motor class="h1" name="r_arm_shy_actuator" joint="r_arm_shy" ctrlrange="-40 40"/>
    <motor class="h1" name="r_arm_shx_actuator" joint="r_arm_shx" ctrlrange="-40 40"/>
    <motor class="h1" name="r_arm_shz_actuator" joint="r_arm_shz" ctrlrange="-18 18"/>
    <motor class="h1" name="right_elbow_actuator" joint="right_elbow" ctrlrange="-18 18"/>
</actuator>
<equality>
    <joint name="phalanx_1_1_eq_virtual_2_1" class="b" joint1="phalanx_1_1_to_virtual_2_1" joint2="virtual_2_1_to_phalanx_2_1"/>
    <joint name="phalanx_2_1_eq_virtual_3_1" class="b" joint1="phalanx_2_1_to_virtual_3_1" joint2="virtual_3_1_to_phalanx_3_1"/>
    <joint name="phalanx_3_1_eq_virtual_4_1" class="b" joint1="phalanx_3_1_to_virtual_4_1" joint2="virtual_4_1_to_reverse_phalanx_1"/>
    <joint name="reverse_phalanx_1_eq_virtual_5_1" class="b" joint1="reverse_phalanx_1_to_virtual_5_1" joint2="virtual_5_1_to_rollover_phalanx_1"/>
    <joint name="rollover_phalanx_1_eq_virtual_6_1" class="b" joint1="rollover_phalanx_1_to_virtual_6_1" joint2="virtual_6_1_to_phalanx_4_1"/>
    <joint name="phalanx_4_1_eq_virtual_7_1" class="b" joint1="phalanx_4_1_to_virtual_7_1" joint2="virtual_7_1_to_distal_phalanx_1"/>
    <joint name="phalanx_1_2_eq_virtual_2_2" class="b" joint1="phalanx_1_2_to_virtual_2_2" joint2="virtual_2_2_to_phalanx_2_2"/>
    <joint name="phalanx_2_2_eq_virtual_3_2" class="b" joint1="phalanx_2_2_to_virtual_3_2" joint2="virtual_3_2_to_phalanx_3_2"/>
    <joint name="phalanx_3_2_eq_virtual_4_2" class="b" joint1="phalanx_3_2_to_virtual_4_2" joint2="virtual_4_2_to_reverse_phalanx_2"/>
    <joint name="reverse_phalanx_2_eq_virtual_5_2" class="b" joint1="reverse_phalanx_2_to_virtual_5_2" joint2="virtual_5_2_to_rollover_phalanx_2"/>
    <joint name="rollover_phalanx_2_eq_virtual_6_2" class="b" joint1="rollover_phalanx_2_to_virtual_6_2" joint2="virtual_6_2_to_phalanx_4_2"/>
    <joint name="phalanx_4_2_eq_virtual_7_2" class="b" joint1="phalanx_4_2_to_virtual_7_2" joint2="virtual_7_2_to_distal_phalanx_2"/>
    <joint name="phalanx_1_3_eq_virtual_2_3" class="b" joint1="phalanx_1_3_to_virtual_2_3" joint2="virtual_2_3_to_phalanx_2_3"/>
    <joint name="phalanx_2_3_eq_virtual_3_3" class="b" joint1="phalanx_2_3_to_virtual_3_3" joint2="virtual_3_3_to_phalanx_3_3"/>
    <joint name="phalanx_3_3_eq_virtual_4_3" class="b" joint1="phalanx_3_3_to_virtual_4_3" joint2="virtual_4_3_to_reverse_phalanx_3"/>
    <joint name="reverse_phalanx_3_eq_virtual_5_3" class="b" joint1="reverse_phalanx_3_to_virtual_5_3" joint2="virtual_5_3_to_rollover_phalanx_3"/>
    <joint name="rollover_phalanx_3_eq_virtual_6_3" class="b" joint1="rollover_phalanx_3_to_virtual_6_3" joint2="virtual_6_3_to_phalanx_4_3"/>
    <joint name="phalanx_4_3_eq_virtual_7_3" class="b" joint1="phalanx_4_3_to_virtual_7_3" joint2="virtual_7_3_to_distal_phalanx_3"/>
    <joint name="phalanx_1_4_eq_virtual_2_4" class="b" joint1="phalanx_1_4_to_virtual_2_4" joint2="virtual_2_4_to_phalanx_2_4"/>
    <joint name="phalanx_2_4_eq_virtual_3_4" class="b" joint1="phalanx_2_4_to_virtual_3_4" joint2="virtual_3_4_to_phalanx_3_4"/>
    <joint name="phalanx_3_4_eq_virtual_4_4" class="b" joint1="phalanx_3_4_to_virtual_4_4" joint2="virtual_4_4_to_reverse_phalanx_4"/>
    <joint name="reverse_phalanx_4_eq_virtual_5_4" class="b" joint1="reverse_phalanx_4_to_virtual_5_4" joint2="virtual_5_4_to_rollover_phalanx_4"/>
    <joint name="rollover_phalanx_4_eq_virtual_6_4" class="b" joint1="rollover_phalanx_4_to_virtual_6_4" joint2="virtual_6_4_to_phalanx_4_4"/>
    <joint name="phalanx_4_4_eq_virtual_7_4" class="b" joint1="phalanx_4_4_to_virtual_7_4" joint2="virtual_7_4_to_distal_phalanx_4"/>
    <joint name="phalanx_1_5_eq_virtual_2_5" class="b" joint1="phalanx_1_5_to_virtual_2_5" joint2="virtual_2_5_to_phalanx_2_5"/>
    <joint name="phalanx_2_5_eq_virtual_3_5" class="b" joint1="phalanx_2_5_to_virtual_3_5" joint2="virtual_3_5_to_phalanx_3_5"/>
    <joint name="phalanx_3_5_eq_virtual_4_5" class="b" joint1="phalanx_3_5_to_virtual_4_5" joint2="virtual_4_5_to_reverse_phalanx_5"/>
    <joint name="reverse_phalanx_5_eq_virtual_5_5" class="b" joint1="reverse_phalanx_5_to_virtual_5_5" joint2="virtual_5_5_to_rollover_phalanx_5"/>
    <joint name="rollover_phalanx_5_eq_virtual_6_5" class="b" joint1="rollover_phalanx_5_to_virtual_6_5" joint2="virtual_6_5_to_phalanx_4_5"/>
    <joint name="phalanx_4_5_eq_virtual_7_5" class="b" joint1="phalanx_4_5_to_virtual_7_5" joint2="virtual_7_5_to_distal_phalanx_5"/>
    <connect name="frontal_arch_connect_rollover_phalanx_1" class="b" solimp="0.94999999999999996 0.98999999999999999 0.0001 0.5 4" body1="frontal_arch" body2="rollover_phalanx_1" anchor="0.135632 0 0.028000000000000001"/>
    <connect name="frontal_arch_connect_rollover_phalanx_2" class="b" solimp="0.94999999999999996 0.98999999999999999 0.0001 0.5 4" body1="frontal_arch" body2="rollover_phalanx_2" anchor="0.135632 0 0.013000000000000001"/>
    <connect name="frontal_arch_connect_rollover_phalanx_3" class="b" solimp="0.94999999999999996 0.98999999999999999 0.0001 0.5 4" body1="frontal_arch" body2="rollover_phalanx_3" anchor="0.135632 0 -0.0019999999999999983"/>
    <connect name="frontal_arch_connect_rollover_phalanx_4" class="b" solimp="0.94999999999999996 0.98999999999999999 0.0001 0.5 4" body1="frontal_arch" body2="rollover_phalanx_4" anchor="0.135632 0 -0.016999999999999998"/>
    <connect name="frontal_arch_connect_rollover_phalanx_5" class="b" solimp="0.94999999999999996 0.98999999999999999 0.0001 0.5 4" body1="frontal_arch" body2="rollover_phalanx_5" anchor="0.135632 0 -0.032000000000000001"/>
  </equality>
  <tendon>
    <spatial name="tendon_1" class="b" limited="true" range="0 0.1953916264212083" width="0.00075000000000000002" rgba="0.90000000000000002 0.69999999999999996 0.10000000000000001 1" springlength="0.2" stiffness="0.10000000000000001">
      <site site="site_roll_virtual_1_1"/>
      <geom geom="roll_virtual_1_1" sidesite="site_roll_virtual_1_1"/>
      <site site="site_roll_phalanx_1_1"/>
      <geom geom="roll_phalanx_1_1" sidesite="site_roll_phalanx_1_1"/>
      <site site="site_roll_virtual_2_1"/>
      <geom geom="roll_virtual_2_1" sidesite="site_roll_virtual_2_1"/>
      <site site="site_roll_phalanx_2_1"/>
      <geom geom="roll_phalanx_2_1" sidesite="site_roll_phalanx_2_1"/>
      <site site="site_roll_virtual_3_1"/>
      <geom geom="roll_virtual_3_1" sidesite="site_roll_virtual_3_1"/>
      <site site="site_roll_phalanx_3_1"/>
      <geom geom="roll_phalanx_3_1" sidesite="site_roll_phalanx_3_1"/>
      <site site="site_roll_virtual_4_1"/>
      <geom geom="roll_virtual_4_1" sidesite="site_roll_virtual_4_1"/>
      <site site="site_roll_reverse_phalanx_1"/>
      <geom geom="roll_reverse_phalanx_1" sidesite="site_roll_reverse_phalanx_1"/>
      <site site="site_roll_virtual_5_1"/>
      <geom geom="roll_virtual_5_1" sidesite="site_roll_virtual_5_1"/>
      <site site="site_roll_rollover_phalanx_1"/>
      <geom geom="roll_rollover_phalanx_1" sidesite="site_roll_rollover_phalanx_1"/>
      <site site="site_roll_virtual_6_1"/>
      <geom geom="roll_virtual_6_1" sidesite="site_roll_virtual_6_1"/>
      <site site="site_roll_phalanx_4_1"/>
      <geom geom="roll_phalanx_4_1" sidesite="site_roll_phalanx_4_1"/>
      <site site="site_roll_virtual_7_1"/>
      <geom geom="roll_virtual_7_1" sidesite="site_roll_virtual_7_1"/>
      <site site="site_roll_distal_phalanx_1"/>
      <geom geom="roll_distal_phalanx_1" sidesite="site_roll_distal_phalanx_1"/>
      <site site="site_roll_distal_phalanx_1_extreme"/>
    </spatial>
    <spatial name="tendon_2" class="b" limited="true" range="0 0.1953916264212083" width="0.00075000000000000002" rgba="0.90000000000000002 0.69999999999999996 0.10000000000000001 1" springlength="0.2" stiffness="0.10000000000000001">
      <site site="site_roll_virtual_1_2"/>
      <geom geom="roll_virtual_1_2" sidesite="site_roll_virtual_1_2"/>
      <site site="site_roll_phalanx_1_2"/>
      <geom geom="roll_phalanx_1_2" sidesite="site_roll_phalanx_1_2"/>
      <site site="site_roll_virtual_2_2"/>
      <geom geom="roll_virtual_2_2" sidesite="site_roll_virtual_2_2"/>
      <site site="site_roll_phalanx_2_2"/>
      <geom geom="roll_phalanx_2_2" sidesite="site_roll_phalanx_2_2"/>
      <site site="site_roll_virtual_3_2"/>
      <geom geom="roll_virtual_3_2" sidesite="site_roll_virtual_3_2"/>
      <site site="site_roll_phalanx_3_2"/>
      <geom geom="roll_phalanx_3_2" sidesite="site_roll_phalanx_3_2"/>
      <site site="site_roll_virtual_4_2"/>
      <geom geom="roll_virtual_4_2" sidesite="site_roll_virtual_4_2"/>
      <site site="site_roll_reverse_phalanx_2"/>
      <geom geom="roll_reverse_phalanx_2" sidesite="site_roll_reverse_phalanx_2"/>
      <site site="site_roll_virtual_5_2"/>
      <geom geom="roll_virtual_5_2" sidesite="site_roll_virtual_5_2"/>
      <site site="site_roll_rollover_phalanx_2"/>
      <geom geom="roll_rollover_phalanx_2" sidesite="site_roll_rollover_phalanx_2"/>
      <site site="site_roll_virtual_6_2"/>
      <geom geom="roll_virtual_6_2" sidesite="site_roll_virtual_6_2"/>
      <site site="site_roll_phalanx_4_2"/>
      <geom geom="roll_phalanx_4_2" sidesite="site_roll_phalanx_4_2"/>
      <site site="site_roll_virtual_7_2"/>
      <geom geom="roll_virtual_7_2" sidesite="site_roll_virtual_7_2"/>
      <site site="site_roll_distal_phalanx_2"/>
      <geom geom="roll_distal_phalanx_2" sidesite="site_roll_distal_phalanx_2"/>
      <site site="site_roll_distal_phalanx_2_extreme"/>
    </spatial>
    <spatial name="tendon_3" class="b" limited="true" range="0 0.1953916264212083" width="0.00075000000000000002" rgba="0.90000000000000002 0.69999999999999996 0.10000000000000001 1" springlength="0.2" stiffness="0.10000000000000001">
      <site site="site_roll_virtual_1_3"/>
      <geom geom="roll_virtual_1_3" sidesite="site_roll_virtual_1_3"/>
      <site site="site_roll_phalanx_1_3"/>
      <geom geom="roll_phalanx_1_3" sidesite="site_roll_phalanx_1_3"/>
      <site site="site_roll_virtual_2_3"/>
      <geom geom="roll_virtual_2_3" sidesite="site_roll_virtual_2_3"/>
      <site site="site_roll_phalanx_2_3"/>
      <geom geom="roll_phalanx_2_3" sidesite="site_roll_phalanx_2_3"/>
      <site site="site_roll_virtual_3_3"/>
      <geom geom="roll_virtual_3_3" sidesite="site_roll_virtual_3_3"/>
      <site site="site_roll_phalanx_3_3"/>
      <geom geom="roll_phalanx_3_3" sidesite="site_roll_phalanx_3_3"/>
      <site site="site_roll_virtual_4_3"/>
      <geom geom="roll_virtual_4_3" sidesite="site_roll_virtual_4_3"/>
      <site site="site_roll_reverse_phalanx_3"/>
      <geom geom="roll_reverse_phalanx_3" sidesite="site_roll_reverse_phalanx_3"/>
      <site site="site_roll_virtual_5_3"/>
      <geom geom="roll_virtual_5_3" sidesite="site_roll_virtual_5_3"/>
      <site site="site_roll_rollover_phalanx_3"/>
      <geom geom="roll_rollover_phalanx_3" sidesite="site_roll_rollover_phalanx_3"/>
      <site site="site_roll_virtual_6_3"/>
      <geom geom="roll_virtual_6_3" sidesite="site_roll_virtual_6_3"/>
      <site site="site_roll_phalanx_4_3"/>
      <geom geom="roll_phalanx_4_3" sidesite="site_roll_phalanx_4_3"/>
      <site site="site_roll_virtual_7_3"/>
      <geom geom="roll_virtual_7_3" sidesite="site_roll_virtual_7_3"/>
      <site site="site_roll_distal_phalanx_3"/>
      <geom geom="roll_distal_phalanx_3" sidesite="site_roll_distal_phalanx_3"/>
      <site site="site_roll_distal_phalanx_3_extreme"/>
    </spatial>
    <spatial name="tendon_4" class="b" limited="true" range="0 0.1953916264212083" width="0.00075000000000000002" rgba="0.90000000000000002 0.69999999999999996 0.10000000000000001 1" springlength="0.2" stiffness="0.10000000000000001">
      <site site="site_roll_virtual_1_4"/>
      <geom geom="roll_virtual_1_4" sidesite="site_roll_virtual_1_4"/>
      <site site="site_roll_phalanx_1_4"/>
      <geom geom="roll_phalanx_1_4" sidesite="site_roll_phalanx_1_4"/>
      <site site="site_roll_virtual_2_4"/>
      <geom geom="roll_virtual_2_4" sidesite="site_roll_virtual_2_4"/>
      <site site="site_roll_phalanx_2_4"/>
      <geom geom="roll_phalanx_2_4" sidesite="site_roll_phalanx_2_4"/>
      <site site="site_roll_virtual_3_4"/>
      <geom geom="roll_virtual_3_4" sidesite="site_roll_virtual_3_4"/>
      <site site="site_roll_phalanx_3_4"/>
      <geom geom="roll_phalanx_3_4" sidesite="site_roll_phalanx_3_4"/>
      <site site="site_roll_virtual_4_4"/>
      <geom geom="roll_virtual_4_4" sidesite="site_roll_virtual_4_4"/>
      <site site="site_roll_reverse_phalanx_4"/>
      <geom geom="roll_reverse_phalanx_4" sidesite="site_roll_reverse_phalanx_4"/>
      <site site="site_roll_virtual_5_4"/>
      <geom geom="roll_virtual_5_4" sidesite="site_roll_virtual_5_4"/>
      <site site="site_roll_rollover_phalanx_4"/>
      <geom geom="roll_rollover_phalanx_4" sidesite="site_roll_rollover_phalanx_4"/>
      <site site="site_roll_virtual_6_4"/>
      <geom geom="roll_virtual_6_4" sidesite="site_roll_virtual_6_4"/>
      <site site="site_roll_phalanx_4_4"/>
      <geom geom="roll_phalanx_4_4" sidesite="site_roll_phalanx_4_4"/>
      <site site="site_roll_virtual_7_4"/>
      <geom geom="roll_virtual_7_4" sidesite="site_roll_virtual_7_4"/>
      <site site="site_roll_distal_phalanx_4"/>
      <geom geom="roll_distal_phalanx_4" sidesite="site_roll_distal_phalanx_4"/>
      <site site="site_roll_distal_phalanx_4_extreme"/>
    </spatial>
    <spatial name="tendon_5" class="b" limited="true" range="0 0.1953916264212083" width="0.00075000000000000002" rgba="0.90000000000000002 0.69999999999999996 0.10000000000000001 1" springlength="0.2" stiffness="0.10000000000000001">
      <site site="site_roll_virtual_1_5"/>
      <geom geom="roll_virtual_1_5" sidesite="site_roll_virtual_1_5"/>
      <site site="site_roll_phalanx_1_5"/>
      <geom geom="roll_phalanx_1_5" sidesite="site_roll_phalanx_1_5"/>
      <site site="site_roll_virtual_2_5"/>
      <geom geom="roll_virtual_2_5" sidesite="site_roll_virtual_2_5"/>
      <site site="site_roll_phalanx_2_5"/>
      <geom geom="roll_phalanx_2_5" sidesite="site_roll_phalanx_2_5"/>
      <site site="site_roll_virtual_3_5"/>
      <geom geom="roll_virtual_3_5" sidesite="site_roll_virtual_3_5"/>
      <site site="site_roll_phalanx_3_5"/>
      <geom geom="roll_phalanx_3_5" sidesite="site_roll_phalanx_3_5"/>
      <site site="site_roll_virtual_4_5"/>
      <geom geom="roll_virtual_4_5" sidesite="site_roll_virtual_4_5"/>
      <site site="site_roll_reverse_phalanx_5"/>
      <geom geom="roll_reverse_phalanx_5" sidesite="site_roll_reverse_phalanx_5"/>
      <site site="site_roll_virtual_5_5"/>
      <geom geom="roll_virtual_5_5" sidesite="site_roll_virtual_5_5"/>
      <site site="site_roll_rollover_phalanx_5"/>
      <geom geom="roll_rollover_phalanx_5" sidesite="site_roll_rollover_phalanx_5"/>
      <site site="site_roll_virtual_6_5"/>
      <geom geom="roll_virtual_6_5" sidesite="site_roll_virtual_6_5"/>
      <site site="site_roll_phalanx_4_5"/>
      <geom geom="roll_phalanx_4_5" sidesite="site_roll_phalanx_4_5"/>
      <site site="site_roll_virtual_7_5"/>
      <geom geom="roll_virtual_7_5" sidesite="site_roll_virtual_7_5"/>
      <site site="site_roll_distal_phalanx_5"/>
      <geom geom="roll_distal_phalanx_5" sidesite="site_roll_distal_phalanx_5"/>
      <site site="site_roll_distal_phalanx_5_extreme"/>
    </spatial>
    <spatial name="back_spring_r" class="b" limited="true" range="0.025000000000000001 0.035499999999999997" width="0.0015" rgba="0.29999999999999999 0.40000000000000002 0.45000000000000001 0.5" springlength="0.027" stiffness="39794">
      <site site="site_posterior_spring_r"/>
      <site site="site_heel_spring_r"/>
    </spatial>
    <spatial name="back_spring_l" class="b" limited="true" range="0.025000000000000001 0.035499999999999997" width="0.0015" rgba="0.29999999999999999 0.34999999999999998 0.40000000000000002 0.59999999999999998" springlength="0.027" stiffness="39794">
      <site site="site_posterior_spring_l"/>
      <site site="site_heel_spring_l"/>
    </spatial>
  </tendon>
</mujoco>
